Workbook

Sheet BC01 (RAC)
A1: ESTUDOS HIDROLÓGICOS
A2: Método Racional | Q2: UTILIZAR TABELA QUADRO DE CHUVAS ISOZONAS DADOS PLUVIOMÉTRICOS
B3: Estaca: | E3: 33 | F3: + | G3: 0.46 | T3: DECLIVIDADE EFETIVA (%): | U3: ='PERFIL BC01'!C17 -> 1.90558
B4: VIA : | E4: GO-116 | F4: GREIDE | K4: TEMPO DE RECORRÊNCIA : | N4: 15 | O4: anos | T4: DECLIVIDADE MÉDIA (%): | U4: =100*(E8/(E7*1000)) -> 2.2520069
B5: CURSO D'ÁGUA : | E5: Sem talvegue permanente | K5: TEMPO DE RECORRÊNCIA : | N5: 25 | O5: anos
B6: ÁREA DE CONTRIBUIÇÃO (km²) : | E6: =VLOOKUP(F10,'AUX BACIAS'!$A$2:$D$10,3,0) -> 1.0943532 | K6: TEMPO DE RECORRÊNCIA : | N6: 50 | O6: anos
B7: COMP. DO TALVEGUE (km) : | E7: =(VLOOKUP(F10,'AUX BACIAS'!$A$2:$D$10,4,0)/1000) -> 2.3534563 | K7: TEMPO DE RECORRÊNCIA : | N7: 100 | O7: anos
B8: DESNÍVEL (m) : | E8: ='PERFIL BC01'!C3-'PERFIL BC01'!C13 -> 53 | K8: COEFICIENTE C: | O8: =H26 -> 0.24434
B9: DECLIVIDADE EFETIVA (%) : | E9: =IF(U3>U4,U4,U3) -> 1.90558 | K9: TEMPO DE CONCENTRAÇÃO Tc (h) : | O9: =IF(E6<=0.8,0.39*(E7^2/E9)^0.385,0.59*(E7^2/E9)^0.385) -> 0.88972395
E10: Nº Bacia: | F10: {=MID(RIGHT(CELL("nome.arquivo",A1),LEN(CELL("nome.arquivo",A1)) - SEARCH("]",CELL("nome.arquivo",A1))),1,4)} -> BC01
B11: Tipo de Relevo | C11: =IF(E9<=2,"Plano",IF(AND(E9>2,E9<=5),"Levemente ondulado",IF(AND(E9>5,E9<=10),"Ondulado",IF(AND(E9>10,E9<=20),"Muito ondulado",IF(AND(E9>20,E9<=50),"Montanhoso",IF(AND(E9>50,E9<=100),"Muito montanhoso","Escarpado")))))) -> Plano
B12: Orografia | C12: B | J12: CHUVA DE PROJETO | Q12: Auxiliar - Não apagar
B13: * Classificação de orografia segundo a IP 03 – Goinfra – Estudos hidrológicos | J13: TR | K13: D tc (min) | L13: Po (mm) | N13: I (mm/min) | Q13: =IF(M21>MAX(Base_Bueiros!$F$2:$F$10),"Não atende em canal 15 anos. Dimensionar para 25 anos",IF(M21<=MAX(Base_Bueiros!$F$2:$F$4),INDEX(Base_Bueiros!$C$2:$C$4,MATCH(_xlfn.MINIFS(Base_Bueiros!$F$2:$F$4,Base_Bueiros!$F$2:$F$4,">="&M21),Base_Bueiros!$F$2:$F$4,0))&" d="&TEXT(INDEX(Base_Bueiros!$D$2:$D$4,MATCH(_xlfn.MINIFS(Base_Bueiros!$F$2:$F$4,Base_Bueiros!$F$2:$F$4,">="&M21),Base_Bueiros!$F$2:$F$4,0)),"0,00")&"m",IF(M21<=MAX(Base_Bueiros!$F$5:$F$7),INDEX(Base_Bueiros!$C$5:$C$7,MATCH(_xlfn.MINIFS(Base_Bueiros!$F$5:$F$7,Base_Bueiros!$F$5:$F$7,">="&M21),Base_Bueiros!$F$5:$F$7,0))&" d="&TEXT(INDEX(Base_Bueiros!$D$5:$D$7,MATCH(_xlfn.MINIFS(Base_Bueiros!$F$5:$F$7,Base_Bueiros!$F$5:$F$7,">="&M21),Base_Bueiros!$F$5:$F$7,0)),"0,00")&"m",INDEX(Base_Bueiros!$C$8:$C$10,MATCH(_xlfn.MINIFS(Base_Bueiros!$F$8:$F$10,Base_Bueiros!$F$8:$F$10,">="&M21),Base_Bueiros!$F$8:$F$10,0))&" d="&TEXT(INDEX(Base_Bueiros!$D$8:$D$10,MATCH(_xlfn.MINIFS(Base_Bueiros!$F$8:$F$10,Base_Bueiros!$F$8:$F$10,">="&M21),Base_Bueiros!$F$8:$F$10,0)),"0,00")&"m"))) -> BDTC d= d=1,50m | S13: =IF(Q13="Não atende em canal 15 anos. Dimensionar para 25 anos",25,15) -> 15 | X13: =[1]Precip!$AA$5 -> ax | Z13: =[1]Precip!$AC$5 -> b | AB13: =[1]Precip!$AE$5 -> ax (1-24h) | AC13: Método para C
J14: 15 anos | K14: =$O$9*60 -> 53.383437 | L14: =IF($O$9<=1,(X14*LN((K14/60)))+Z14,(AB14*LN((K14/60)))+Z14) -> 80.293326 | N14: =L14/K14 -> 1.5040869 | Q14: =IF(M22>MAX(Base_Bueiros!$F$20:$F$28),"Não atende em orificio 25 anos. Dimensionar para 50 anos",TRIM(IFERROR(LEFT(INDEX(Base_Bueiros!$C$20:$C$28,MATCH(_xlfn.MINIFS(Base_Bueiros!$F$20:$F$28,Base_Bueiros!$F$20:$F$28,">="&M22),Base_Bueiros!$F$20:$F$28,0)),FIND(" OU ",INDEX(Base_Bueiros!$C$20:$C$28,MATCH(_xlfn.MINIFS(Base_Bueiros!$F$20:$F$28,Base_Bueiros!$F$20:$F$28,">="&M22),Base_Bueiros!$F$20:$F$28,0)))-1),INDEX(Base_Bueiros!$C$20:$C$28,MATCH(_xlfn.MINIFS(Base_Bueiros!$F$20:$F$28,Base_Bueiros!$F$20:$F$28,">="&M22),Base_Bueiros!$F$20:$F$28,0))))&" d="&INDEX(Base_Bueiros!$D$20:$D$28,MATCH(_xlfn.MINIFS(Base_Bueiros!$F$20:$F$28,Base_Bueiros!$F$20:$F$28,">="&M22),Base_Bueiros!$F$20:$F$28,0))&"m") -> BDTC d= d=1,20m | S14: =IF(Q14="Não atende em orifício 25 anos. Dimensionar para 50 anos",50,25) -> 25 | W14: 15 | X14: =VLOOKUP(W14,[2]Precip!$Z$12:$AE$18,2) -> 26.41506 | Z14: =VLOOKUP(W14,[2]Precip!$Z$12:$AE$18,4) -> 83.379769 | AB14: =[1]Precip!$AE$14 -> 24.188986 | AC14: =IF(C11="Plano","Tabelado",IF(C11="Ondulado","Tabelado",IF(C11="Montanhoso","Tabelado","Ponderado"))) -> Tabelado
J15: 25 anos | K15: =$O$9*60 -> 53.383437 | L15: =IF($O$9<=1,(X15*LN((K15/60)))+Z15,(AB15*LN((K15/60)))+Z15) -> 88.530892 | N15: =L15/K15 -> 1.6583963 | W15: 25 | X15: =VLOOKUP(W15,[2]Precip!$Z$12:$AE$18,2) -> 29.043207 | Z15: =VLOOKUP(W15,[2]Precip!$Z$12:$AE$18,4) -> 91.924418 | AB15: =[1]Precip!$AE$16 -> 26.572791
J16: 50 anos | K16: =$O$9*60 -> 53.383437 | L16: =IF($O$9<=1,(X16*LN((K16/60)))+Z16,(AB16*LN((K16/60)))+Z16) -> 99.255857 | N16: =L16/K16 -> 1.8593006 | W16: 50 | X16: =VLOOKUP(W16,[2]Precip!$Z$12:$AE$18,2) -> 32.43716 | Z16: =VLOOKUP(W16,[2]Precip!$Z$12:$AE$18,4) -> 103.04595 | AB16: =[1]Precip!$AE$17 -> 29.779923
J17: 100 anos | K17: =$O$9*60 -> 53.383437 | L17: =IF($O$9<=1,(X17*LN((K17/60)))+Z17,(AB17*LN((K17/60)))+Z17) -> 109.5118 | N17: =L17/K17 -> 2.0514191 | W17: 100 | X17: =VLOOKUP(W17,[2]Precip!$Z$12:$AE$18,2) -> 37.177213 | Z17: =VLOOKUP(W17,[2]Precip!$Z$12:$AE$18,4) -> 113.85574 | AB17: =[1]Precip!$AE$18 -> 33.004345
B20: COMPOSIÇÃO DE ÁREA "C" | J20: Resultados | K20: Recorrência | M20: Qmáx
D21: m² | E21: km² | F21: C | G21: % | K21: Q15 = | M21: =0.278*$O$8*(N14*60)*$E$6 -> 6.7084321 | N21: m³/s | Q21: Q(bueiro-canal) | R21: =(1/0.015) -> 66.666667
B22: Área total | D22: =E22*10^6 -> 1094353.2 | E22: =E6 -> 1.0943532 | F22: - | G22: - | H22: - | K22: Q25 = | M22: =0.278*$O$8*(N15*60)*$E$6 -> 7.396673 | N22: m³/s | Q22: Q(bueiro-orifício)
B23: Culturas e pastagens terraceadas | D23: =$D$22*G23 -> 123880.78 | E23: =D23/10^6 -> 0.12388078 | F23: {=_xlfn.LET( _xlpm.superficie,B23, _xlpm.oro,$C$12, _xlpm.terreno,$C$11, _xlpm.metodo,$AC$14, _xlpm.linInicial,MATCH(_xlpm.superficie,C_CN_IP03!$B$4:$B$19,0), _xlpm.lin,_xlpm.linInicial+MATCH(_xlpm.oro,INDEX(C_CN_IP03!$C$4:$C$19,_xlpm.linInicial):INDEX(C_CN_IP03!$C$4:$C$19,_xlpm.linInicial+3),0)-1, IF( _xlpm.metodo="Tabelado", _xlfn.LET( _xlpm.col,MATCH(_xlpm.terreno,C_CN_IP03!$D$2:$I$2,0), INDEX(C_CN_IP03!$D$4:$I$19,_xlpm.lin,_xlpm.col) ), IF( _xlpm.metodo="Ponderado", IF( _xlpm.terreno="Levemente ondulado", AVERAGE( INDEX(C_CN_IP03!$D$4:$I$19,_xlpm.lin,1), INDEX(C_CN_IP03!$D$4:$I$19,_xlpm.lin,3) ), IF( _xlpm.terreno="Muito ondulado", AVERAGE( INDEX(C_CN_IP03!$D$4:$I$19,_xlpm.lin,3), INDEX(C_CN_IP03!$D$4:$I$19,_xlpm.lin,5) ), "Condição de terreno não reconhecida" ) ), "Método não reconhecido" ) ) )} -> 0.2 | G23: 0.1132 | H23: =(G23*(F23)) -> 0.02264 | K23: Q50 = | M23: =0.278*$O$8*(N16*60)*$E$6 -> 8.2927338 | N23: m³/s
B24: Cerrados, pastagens e matas ralas | D24: =$D$22*G24 -> 970472.38 | E24: =D24/10^6 -> 0.97047238 | F24: {=_xlfn.LET( _xlpm.superficie,B24, _xlpm.oro,$C$12, _xlpm.terreno,$C$11, _xlpm.metodo,$AC$14, _xlpm.linInicial,MATCH(_xlpm.superficie,C_CN_IP03!$B$4:$B$19,0), _xlpm.lin,_xlpm.linInicial+MATCH(_xlpm.oro,INDEX(C_CN_IP03!$C$4:$C$19,_xlpm.linInicial):INDEX(C_CN_IP03!$C$4:$C$19,_xlpm.linInicial+3),0)-1, IF( _xlpm.metodo="Tabelado", _xlfn.LET( _xlpm.col,MATCH(_xlpm.terreno,C_CN_IP03!$D$2:$I$2,0), INDEX(C_CN_IP03!$D$4:$I$19,_xlpm.lin,_xlpm.col) ), IF( _xlpm.metodo="Ponderado", IF( _xlpm.terreno="Levemente ondulado", AVERAGE( INDEX(C_CN_IP03!$D$4:$I$19,_xlpm.lin,1), INDEX(C_CN_IP03!$D$4:$I$19,_xlpm.lin,3) ), IF( _xlpm.terreno="Muito ondulado", AVERAGE( INDEX(C_CN_IP03!$D$4:$I$19,_xlpm.lin,3), INDEX(C_CN_IP03!$D$4:$I$19,_xlpm.lin,5) ), "Condição de terreno não reconhecida" ) ), "Método não reconhecido" ) ) )} -> 0.25 | G24: 0.8868 | H24: =(G24*(F24)) -> 0.2217 | K24: Q100 = | M24: =0.278*$O$8*(N17*60)*$E$6 -> 9.1496086 | N24: m³/s
B25: Áreas urbanizadas, Cerrados, pastagens | D25: - | E25: - | F25: - | G25: - | H25: -
B26: C adotado | H26: =SUM(H22:H25) -> 0.24434 | J26: OBRA PROJETADA
B27: * Tabela de coeficientes de C e CN - IP 03 – Goinfra – Estudos hidrológicos | J27: {=IFERROR(_xlfn.LET( _xlpm.Func,"Orif", _xlpm.Funcs,Base_Bueiros!$A$2:$A$37, _xlpm.Tipos,Base_Bueiros!$C$2:$C$37, _xlpm.Dims,Base_Bueiros!$D$2:$D$37, _xlpm.Vazoes,Base_Bueiros!$F$2:$F$37, _xlpm.DimNum,IFERROR(VALUE(TRIM(LEFT(_xlpm.Dims,FIND("x",_xlpm.Dims)-1))),VALUE(_xlpm.Dims)), _xlpm.Linhas,IF(MID(_xlpm.Tipos,2,1)="T",3,IF(MID(_xlpm.Tipos,2,1)="D",2,1)), _xlpm.EhTubular,MID(_xlpm.Tipos,3,1)="T", _xlpm.QNec,IF(ISNUMBER(FIND("Orif",_xlpm.Func)),IF(_xlpm.EhTubular,M22,M23),IF(_xlpm.EhTubular,M21,M22)), _xlpm.FiltroBase,(ISNUMBER(FIND(_xlpm.Func,_xlpm.Funcs)))*(_xlpm.Vazoes>=_xlpm.QNec), _xlpm.TemTubular,SUM(_xlpm.FiltroBase*_xlpm.EhTubular)>0, _xlpm.Filtro,_xlpm.FiltroBase*IF(_xlpm.TemTubular,_xlpm.EhTubular,NOT(_xlpm.EhTubular)), _xlpm.Prior1,IF(_xlpm.EhTubular,_xlpm.DimNum,_xlpm.Linhas), _xlpm.Prior2,IF(_xlpm.EhTubular,_xlpm.Linhas,_xlpm.DimNum), _xlpm.MenorPrior1,_xlfn.AGGREGATE(15,6,_xlpm.Prior1/_xlpm.Filtro,1), _xlpm.MenorPrior2,_xlfn.AGGREGATE(15,6,_xlpm.Prior2/(_xlpm.Filtro*(_xlpm.Prior1=_xlpm.MenorPrior1)),1), _xlpm.MenorVazao,_xlfn.AGGREGATE(15,6,_xlpm.Vazoes/(_xlpm.Filtro*(_xlpm.Prior1=_xlpm.MenorPrior1)*(_xlpm.Prior2=_xlpm.MenorPrior2)),1), _xlpm.Linha,MATCH(1,(_xlpm.Vazoes=_xlpm.MenorVazao)*(_xlpm.Filtro>0),0), _xlpm.Tipo,INDEX(_xlpm.Tipos,_xlpm.Linha), _xlpm.Dim,INDEX(_xlpm.Dims,_xlpm.Linha), _xlpm.EhTubularEscolhido,MID(_xlpm.Tipo,3,1)="T", _xlpm.Tipo&" "&IF(_xlpm.EhTubularEscolhido,_xlpm.Dim&"m",SUBSTITUTE(_xlpm.Dim,"0,00","")&"m") ),"Ponte")} -> BDTC d= 1,20m
J28: *Condição de funcionamento: orifício
J29: *Carga hidráulica: h=1,2*H
J31: OBRA PROJETADA
J32: {=IFERROR(_xlfn.LET( _xlpm.Func,"Canal", _xlpm.Funcs,Base_Bueiros!$A$2:$A$37, _xlpm.Tipos,Base_Bueiros!$C$2:$C$37, _xlpm.Dims,Base_Bueiros!$D$2:$D$37, _xlpm.Vazoes,Base_Bueiros!$F$2:$F$37, _xlpm.DimNum,IFERROR(VALUE(TRIM(LEFT(_xlpm.Dims,FIND("x",_xlpm.Dims)-1))),VALUE(_xlpm.Dims)), _xlpm.Linhas,IF(MID(_xlpm.Tipos,2,1)="T",3,IF(MID(_xlpm.Tipos,2,1)="D",2,1)), _xlpm.EhTubular,MID(_xlpm.Tipos,3,1)="T", _xlpm.QNec,IF(ISNUMBER(FIND("Orif",_xlpm.Func)),IF(_xlpm.EhTubular,M22,M23),IF(_xlpm.EhTubular,M21,M22)), _xlpm.FiltroBase,(ISNUMBER(FIND(_xlpm.Func,_xlpm.Funcs)))*(_xlpm.Vazoes>=_xlpm.QNec), _xlpm.TemTubular,SUM(_xlpm.FiltroBase*_xlpm.EhTubular)>0, _xlpm.Filtro,_xlpm.FiltroBase*IF(_xlpm.TemTubular,_xlpm.EhTubular,NOT(_xlpm.EhTubular)), _xlpm.Prior1,IF(_xlpm.EhTubular,_xlpm.DimNum,_xlpm.Linhas), _xlpm.Prior2,IF(_xlpm.EhTubular,_xlpm.Linhas,_xlpm.DimNum), _xlpm.MenorPrior1,_xlfn.AGGREGATE(15,6,_xlpm.Prior1/_xlpm.Filtro,1), _xlpm.MenorPrior2,_xlfn.AGGREGATE(15,6,_xlpm.Prior2/(_xlpm.Filtro*(_xlpm.Prior1=_xlpm.MenorPrior1)),1), _xlpm.MenorVazao,_xlfn.AGGREGATE(15,6,_xlpm.Vazoes/(_xlpm.Filtro*(_xlpm.Prior1=_xlpm.MenorPrior1)*(_xlpm.Prior2=_xlpm.MenorPrior2)),1), _xlpm.Linha,MATCH(1,(_xlpm.Vazoes=_xlpm.MenorVazao)*(_xlpm.Filtro>0),0), _xlpm.Tipo,INDEX(_xlpm.Tipos,_xlpm.Linha), _xlpm.Dim,INDEX(_xlpm.Dims,_xlpm.Linha), _xlpm.EhTubularEscolhido,MID(_xlpm.Tipo,3,1)="T", _xlpm.Tipo&" "&IF(_xlpm.EhTubularEscolhido,_xlpm.Dim&"m",SUBSTITUTE(_xlpm.Dim,"0,00","")&"m") ),"Ponte")} -> BTTC d= 1,20m
J33: *Condição de funcionamento: canal
J35: OBRA EXISTENTE
J36: ='Apresentação - Est. Hid.'!AK19 -> -

Sheet PERFIL BC01
B2: Ponto | C2: Cota (m) | D2: Distância (m) | E2: Distância Acumulada (Km) | F2: DHn (m) | G2: DLn (km) | H2: Sn (m/km)
B3: C | C3: 681 | D3: 0 | E3: =D3/1000 -> 0 | F3: 0 | G3: 0 | H3: 0 | J3: Validação por macro
B4: 1 | C4: 678 | D4: 250 | E4: =D4/1000 -> 0.25 | F4: =C3-C4 -> 3 | G4: =E4-E3 -> 0.25 | H4: =F4/G4 -> 12 | J4: Sef (m/km) | K4: =(((E13/((G4/SQRT(H4))+(G5/SQRT(H5))+(G6/SQRT(H6))+(G7/SQRT(H7))+(G8/SQRT(H8))+(G9/SQRT(H9))+(G10/SQRT(H10))+(G11/SQRT(H11))+(G12/SQRT(H12))+(G13/SQRT(H13))))^2)/1000)*1000 -> 19.0558
B5: 2 | C5: 673 | D5: =D4+250 -> 500 | E5: =D5/1000 -> 0.5 | F5: =C4-C5 -> 5 | G5: =E5-E4 -> 0.25 | H5: =F5/G5 -> 20 | J5: Sef (m/m) | K5: =((E13/((G4/SQRT(H4))+(G5/SQRT(H5))+(G6/SQRT(H6))+(G7/SQRT(H7))+(G8/SQRT(H8))+(G9/SQRT(H9))+(G10/SQRT(H10))+(G11/SQRT(H11))+(G12/SQRT(H12))+(G13/SQRT(H13))))^2)/1000 -> 0.0190558
B6: 3 | C6: 665 | D6: =D5+250 -> 750 | E6: =D6/1000 -> 0.75 | F6: =C5-C6 -> 8 | G6: =E6-E5 -> 0.25 | H6: =F6/G6 -> 32 | J6: Sef (%) | K6: =(((E13/((G4/SQRT(H4))+(G5/SQRT(H5))+(G6/SQRT(H6))+(G7/SQRT(H7))+(G8/SQRT(H8))+(G9/SQRT(H9))+(G10/SQRT(H10))+(G11/SQRT(H11))+(G12/SQRT(H12))+(G13/SQRT(H13))))^2)/1000)*100 -> 1.90558
B7: 4 | C7: 657 | D7: =D6+250 -> 1000 | E7: =D7/1000 -> 1 | F7: =C6-C7 -> 8 | G7: =E7-E6 -> 0.25 | H7: =F7/G7 -> 32
B8: 5 | C8: 650 | D8: =D7+250 -> 1250 | E8: =D8/1000 -> 1.25 | F8: =C7-C8 -> 7 | G8: =E8-E7 -> 0.25 | H8: =F8/G8 -> 28
B9: 6 | C9: 644 | D9: =D8+250 -> 1500 | E9: =D9/1000 -> 1.5 | F9: =C8-C9 -> 6 | G9: =E9-E8 -> 0.25 | H9: =F9/G9 -> 24
B10: 7 | C10: 638 | D10: =D9+250 -> 1750 | E10: =D10/1000 -> 1.75 | F10: =C9-C10 -> 6 | G10: =E10-E9 -> 0.25 | H10: =F10/G10 -> 24
B11: 8 | C11: 631 | D11: =D10+250 -> 2000 | E11: =D11/1000 -> 2 | F11: =C10-C11 -> 7 | G11: =E11-E10 -> 0.25 | H11: =F11/G11 -> 28
B12: 9 | C12: 628.5 | D12: =D11+250 -> 2250 | E12: =D12/1000 -> 2.25 | F12: =C11-C12 -> 2.5 | G12: =E12-E11 -> 0.25 | H12: =F12/G12 -> 10
B13: E | C13: 628 | D13: ='BC01 (RAC)'!E7*1000 -> 2353.4563 | E13: =D13/1000 -> 2.3534563 | F13: =C12-C13 -> 0.5 | G13: =E13-E12 -> 0.10345635 | H13: =F13/G13 -> 4.8329561
B15: Sef = | C15: =(((E13/((G4/SQRT(H4))+(G5/SQRT(H5))+(G6/SQRT(H6))+(G7/SQRT(H7))+(G8/SQRT(H8))+(G9/SQRT(H9))+(G10/SQRT(H10))+(G11/SQRT(H11))+(G12/SQRT(H12))+(G13/SQRT(H13))))^2)/1000)*1000 -> 19.0558 | D15: (m/km) | E15: m/km
B16: Sef = | C16: =C15/1000 -> 0.0190558 | D16: (m/m) | E16: m/m
B17: Sef = | C17: =C16*100 -> 1.90558 | D17: (%) | E17: %
A34: ="Perfil Longitudinal - "&'BC01 (RAC)'!E5 -> Perfil Longitudinal - Sem talvegue permanente

Sheet BC02 (RAC)
A1: ESTUDOS HIDROLÓGICOS
A2: Método Racional | Q2: UTILIZAR TABELA QUADRO DE CHUVAS ISOZONAS DADOS PLUVIOMÉTRICOS
B3: Estaca: | E3: 49 | F3: + | G3: 18.59 | T3: DECLIVIDADE EFETIVA (%): | U3: ='PERFIL BC02'!C14 -> 2.0261343
B4: VIA : | E4: GO-116 | F4: GREIDE | K4: TEMPO DE RECORRÊNCIA : | N4: 15 | O4: anos | T4: DECLIVIDADE MÉDIA (%): | U4: =100*(E8/(E7*1000)) -> 2.2267027
B5: CURSO D'ÁGUA : | E5: Sem talvegue permanente | K5: TEMPO DE RECORRÊNCIA : | N5: 25 | O5: anos
B6: ÁREA DE CONTRIBUIÇÃO (km²) : | E6: =VLOOKUP(F10,'AUX BACIAS'!$A$2:$D$10,3,0) -> 0.50750119 | K6: TEMPO DE RECORRÊNCIA : | N6: 50 | O6: anos
B7: COMP. DO TALVEGUE (km) : | E7: =(VLOOKUP(F10,'AUX BACIAS'!$A$2:$D$10,4,0)/1000) -> 1.5718309 | K7: TEMPO DE RECORRÊNCIA : | N7: 100 | O7: anos
B8: DESNÍVEL (m) : | E8: =(INDEX('PERFIL BC02'!$C:$C,MATCH("C",'PERFIL BC02'!$B:$B,0))-INDEX('PERFIL BC02'!$C:$C,MATCH("E",'PERFIL BC02'!$B:$B,0))) -> 35 | K8: COEFICIENTE C: | O8: =H26 -> 0.248605
B9: DECLIVIDADE EFETIVA (%) : | E9: =IF(U3>U4,U4,U3) -> 2.0261343 | K9: TEMPO DE CONCENTRAÇÃO Tc (h) : | O9: =IF(E6<=0.8,0.39*(E7^2/E9)^0.385,0.59*(E7^2/E9)^0.385) -> 0.42094932
E10: Nº Bacia: | F10: {=MID(RIGHT(CELL("nome.arquivo",A1),LEN(CELL("nome.arquivo",A1)) - SEARCH("]",CELL("nome.arquivo",A1))),1,4)} -> BC02
B11: Tipo de Relevo | C11: Plano
B12: Orografia | C12: B | J12: CHUVA DE PROJETO | Q12: Auxiliar - Não apagar
B13: * Classificação de orografia segundo a IP 03 – Goinfra – Estudos hidrológicos | J13: TR | K13: D tc (min) | L13: Po (mm) | N13: I (mm/min) | Q13: =IF(M21>MAX(Base_Bueiros!$F$2:$F$10),"Não atende em canal 15 anos. Dimensionar para 25 anos",IF(M21<=MAX(Base_Bueiros!$F$2:$F$4),INDEX(Base_Bueiros!$C$2:$C$4,MATCH(_xlfn.MINIFS(Base_Bueiros!$F$2:$F$4,Base_Bueiros!$F$2:$F$4,">="&M21),Base_Bueiros!$F$2:$F$4,0))&" d="&TEXT(INDEX(Base_Bueiros!$D$2:$D$4,MATCH(_xlfn.MINIFS(Base_Bueiros!$F$2:$F$4,Base_Bueiros!$F$2:$F$4,">="&M21),Base_Bueiros!$F$2:$F$4,0)),"0,00")&"m",IF(M21<=MAX(Base_Bueiros!$F$5:$F$7),INDEX(Base_Bueiros!$C$5:$C$7,MATCH(_xlfn.MINIFS(Base_Bueiros!$F$5:$F$7,Base_Bueiros!$F$5:$F$7,">="&M21),Base_Bueiros!$F$5:$F$7,0))&" d="&TEXT(INDEX(Base_Bueiros!$D$5:$D$7,MATCH(_xlfn.MINIFS(Base_Bueiros!$F$5:$F$7,Base_Bueiros!$F$5:$F$7,">="&M21),Base_Bueiros!$F$5:$F$7,0)),"0,00")&"m",INDEX(Base_Bueiros!$C$8:$C$10,MATCH(_xlfn.MINIFS(Base_Bueiros!$F$8:$F$10,Base_Bueiros!$F$8:$F$10,">="&M21),Base_Bueiros!$F$8:$F$10,0))&" d="&TEXT(INDEX(Base_Bueiros!$D$8:$D$10,MATCH(_xlfn.MINIFS(Base_Bueiros!$F$8:$F$10,Base_Bueiros!$F$8:$F$10,">="&M21),Base_Bueiros!$F$8:$F$10,0)),"0,00")&"m"))) -> BDTC d= d=1,50m | S13: =IF(Q13="Não atende em canal 15 anos. Dimensionar para 25 anos",25,15) -> 15 | X13: ='BC01 (RAC)'!X13 -> ax | Z13: ='BC01 (RAC)'!Z13 -> b | AB13: ='BC01 (RAC)'!AB13 -> ax (1-24h) | AC13: Método para C
J14: 15 anos | K14: =$O$9*60 -> 25.256959 | L14: =IF($O$9<=1,(X14*LN((K14/60)))+Z14,(AB14*LN((K14/60)))+Z14) -> 60.524327 | N14: =L14/K14 -> 2.3963426 | Q14: =IF(M22>MAX(Base_Bueiros!$F$20:$F$28),"Não atende em orificio 25 anos. Dimensionar para 50 anos",TRIM(IFERROR(LEFT(INDEX(Base_Bueiros!$C$20:$C$28,MATCH(_xlfn.MINIFS(Base_Bueiros!$F$20:$F$28,Base_Bueiros!$F$20:$F$28,">="&M22),Base_Bueiros!$F$20:$F$28,0)),FIND(" OU ",INDEX(Base_Bueiros!$C$20:$C$28,MATCH(_xlfn.MINIFS(Base_Bueiros!$F$20:$F$28,Base_Bueiros!$F$20:$F$28,">="&M22),Base_Bueiros!$F$20:$F$28,0)))-1),INDEX(Base_Bueiros!$C$20:$C$28,MATCH(_xlfn.MINIFS(Base_Bueiros!$F$20:$F$28,Base_Bueiros!$F$20:$F$28,">="&M22),Base_Bueiros!$F$20:$F$28,0))))&" d="&INDEX(Base_Bueiros!$D$20:$D$28,MATCH(_xlfn.MINIFS(Base_Bueiros!$F$20:$F$28,Base_Bueiros!$F$20:$F$28,">="&M22),Base_Bueiros!$F$20:$F$28,0))&"m") -> BSTC d= d=1,50m | S14: =IF(Q14="Não atende em orifício 25 anos. Dimensionar para 50 anos",50,25) -> 25 | W14: 15 | X14: ='BC01 (RAC)'!X14 -> 26.41506 | Z14: ='BC01 (RAC)'!Z14 -> 83.379769 | AB14: ='BC01 (RAC)'!AB14 -> 24.188986 | AC14: =IF(C11="Plano","Tabelado",IF(C11="Ondulado","Tabelado",IF(C11="Montanhoso","Tabelado","Ponderado"))) -> Tabelado
J15: 25 anos | K15: =$O$9*60 -> 25.256959 | L15: =IF($O$9<=1,(X15*LN((K15/60)))+Z15,(AB15*LN((K15/60)))+Z15) -> 66.794991 | N15: =L15/K15 -> 2.6446173 | W15: 25 | X15: ='BC01 (RAC)'!X15 -> 29.043207 | Z15: ='BC01 (RAC)'!Z15 -> 91.924418 | AB15: ='BC01 (RAC)'!AB15 -> 26.572791
J16: 50 anos | K16: =$O$9*60 -> 25.256959 | L16: =IF($O$9<=1,(X16*LN((K16/60)))+Z16,(AB16*LN((K16/60)))+Z16) -> 74.979925 | N16: =L16/K16 -> 2.9686838 | W16: 50 | X16: ='BC01 (RAC)'!X16 -> 32.43716 | Z16: ='BC01 (RAC)'!Z16 -> 103.04595 | AB16: ='BC01 (RAC)'!AB16 -> 29.779923
J17: 100 anos | K17: =$O$9*60 -> 25.256959 | L17: =IF($O$9<=1,(X17*LN((K17/60)))+Z17,(AB17*LN((K17/60)))+Z17) -> 81.688423 | N17: =L17/K17 -> 3.2342937 | W17: 100 | X17: ='BC01 (RAC)'!X17 -> 37.177213 | Z17: ='BC01 (RAC)'!Z17 -> 113.85574 | AB17: ='BC01 (RAC)'!AB17 -> 33.004345
B20: COMPOSIÇÃO DE ÁREA "C" | J20: Resultados | K20: Recorrência | M20: Qmáx
D21: m² | E21: km² | F21: C | G21: % | K21: Q15 = | M21: =0.278*$O$8*(N14*60)*$E$6 -> 5.0430338 | N21: m³/s
B22: Área total | D22: =E22*10^6 -> 507501.19 | E22: =E6 -> 0.50750119 | F22: - | G22: - | H22: - | K22: Q25 = | M22: =0.278*$O$8*(N15*60)*$E$6 -> 5.5655207 | N22: m³/s
B23: Culturas e pastagens terraceadas | D23: =$D$22*G23 -> 14159.283 | E23: =D23/10^6 -> 0.014159283 | F23: {=_xlfn.LET( _xlpm.superficie,B23, _xlpm.oro,$C$12, _xlpm.terreno,$C$11, _xlpm.metodo,$AC$14, _xlpm.linInicial,MATCH(_xlpm.superficie,C_CN_IP03!$B$4:$B$19,0), _xlpm.lin,_xlpm.linInicial+MATCH(_xlpm.oro,INDEX(C_CN_IP03!$C$4:$C$19,_xlpm.linInicial):INDEX(C_CN_IP03!$C$4:$C$19,_xlpm.linInicial+3),0)-1, IF( _xlpm.metodo="Tabelado", _xlfn.LET( _xlpm.col,MATCH(_xlpm.terreno,C_CN_IP03!$D$2:$I$2,0), INDEX(C_CN_IP03!$D$4:$I$19,_xlpm.lin,_xlpm.col) ), IF( _xlpm.metodo="Ponderado", IF( _xlpm.terreno="Levemente ondulado", AVERAGE( INDEX(C_CN_IP03!$D$4:$I$19,_xlpm.lin,1), INDEX(C_CN_IP03!$D$4:$I$19,_xlpm.lin,3) ), IF( _xlpm.terreno="Muito ondulado", AVERAGE( INDEX(C_CN_IP03!$D$4:$I$19,_xlpm.lin,3), INDEX(C_CN_IP03!$D$4:$I$19,_xlpm.lin,5) ), "Condição de terreno não reconhecida" ) ), "Método não reconhecido" ) ) )} -> 0.2 | G23: 0.0279 | H23: =(G23*(F23)) -> 0.00558 | K23: Q50 = | M23: =0.278*$O$8*(N16*60)*$E$6 -> 6.2475092 | N23: m³/s
B24: Cerrados, pastagens e matas ralas | D24: =$D$22*G24 -> 493341.9 | E24: =D24/10^6 -> 0.4933419 | F24: {=_xlfn.LET( _xlpm.superficie,B24, _xlpm.oro,$C$12, _xlpm.terreno,$C$11, _xlpm.metodo,$AC$14, _xlpm.linInicial,MATCH(_xlpm.superficie,C_CN_IP03!$B$4:$B$19,0), _xlpm.lin,_xlpm.linInicial+MATCH(_xlpm.oro,INDEX(C_CN_IP03!$C$4:$C$19,_xlpm.linInicial):INDEX(C_CN_IP03!$C$4:$C$19,_xlpm.linInicial+3),0)-1, IF( _xlpm.metodo="Tabelado", _xlfn.LET( _xlpm.col,MATCH(_xlpm.terreno,C_CN_IP03!$D$2:$I$2,0), INDEX(C_CN_IP03!$D$4:$I$19,_xlpm.lin,_xlpm.col) ), IF( _xlpm.metodo="Ponderado", IF( _xlpm.terreno="Levemente ondulado", AVERAGE( INDEX(C_CN_IP03!$D$4:$I$19,_xlpm.lin,1), INDEX(C_CN_IP03!$D$4:$I$19,_xlpm.lin,3) ), IF( _xlpm.terreno="Muito ondulado", AVERAGE( INDEX(C_CN_IP03!$D$4:$I$19,_xlpm.lin,3), INDEX(C_CN_IP03!$D$4:$I$19,_xlpm.lin,5) ), "Condição de terreno não reconhecida" ) ), "Método não reconhecido" ) ) )} -> 0.25 | G24: 0.9721 | H24: =(G24*(F24)) -> 0.243025 | K24: Q100 = | M24: =0.278*$O$8*(N17*60)*$E$6 -> 6.8064776 | N24: m³/s
B25: Áreas urbanizadas, Cerrados, pastagens | D25: - | E25: - | F25: - | G25: - | H25: -
B26: C adotado | H26: =(SUM(H23:H25)) -> 0.248605 | J26: OBRA PROJETADA
B27: * Tabela de coeficientes de C e CN - IP 03 – Goinfra – Estudos hidrológicos | J27: {=IFERROR(_xlfn.LET( _xlpm.Func,"Orif", _xlpm.Funcs,Base_Bueiros!$A$2:$A$37, _xlpm.Tipos,Base_Bueiros!$C$2:$C$37, _xlpm.Dims,Base_Bueiros!$D$2:$D$37, _xlpm.Vazoes,Base_Bueiros!$F$2:$F$37, _xlpm.DimNum,IFERROR(VALUE(TRIM(LEFT(_xlpm.Dims,FIND("x",_xlpm.Dims)-1))),VALUE(_xlpm.Dims)), _xlpm.Linhas,IF(MID(_xlpm.Tipos,2,1)="T",3,IF(MID(_xlpm.Tipos,2,1)="D",2,1)), _xlpm.EhTubular,MID(_xlpm.Tipos,3,1)="T", _xlpm.QNec,IF(ISNUMBER(FIND("Orif",_xlpm.Func)),IF(_xlpm.EhTubular,M22,M23),IF(_xlpm.EhTubular,M21,M22)), _xlpm.FiltroBase,(ISNUMBER(FIND(_xlpm.Func,_xlpm.Funcs)))*(_xlpm.Vazoes>=_xlpm.QNec), _xlpm.TemTubular,SUM(_xlpm.FiltroBase*_xlpm.EhTubular)>0, _xlpm.Filtro,_xlpm.FiltroBase*IF(_xlpm.TemTubular,_xlpm.EhTubular,NOT(_xlpm.EhTubular)), _xlpm.Prior1,IF(_xlpm.EhTubular,_xlpm.DimNum,_xlpm.Linhas), _xlpm.Prior2,IF(_xlpm.EhTubular,_xlpm.Linhas,_xlpm.DimNum), _xlpm.MenorPrior1,_xlfn.AGGREGATE(15,6,_xlpm.Prior1/_xlpm.Filtro,1), _xlpm.MenorPrior2,_xlfn.AGGREGATE(15,6,_xlpm.Prior2/(_xlpm.Filtro*(_xlpm.Prior1=_xlpm.MenorPrior1)),1), _xlpm.MenorVazao,_xlfn.AGGREGATE(15,6,_xlpm.Vazoes/(_xlpm.Filtro*(_xlpm.Prior1=_xlpm.MenorPrior1)*(_xlpm.Prior2=_xlpm.MenorPrior2)),1), _xlpm.Linha,MATCH(1,(_xlpm.Vazoes=_xlpm.MenorVazao)*(_xlpm.Filtro>0),0), _xlpm.Tipo,INDEX(_xlpm.Tipos,_xlpm.Linha), _xlpm.Dim,INDEX(_xlpm.Dims,_xlpm.Linha), _xlpm.EhTubularEscolhido,MID(_xlpm.Tipo,3,1)="T", _xlpm.Tipo&" "&IF(_xlpm.EhTubularEscolhido,_xlpm.Dim&"m",SUBSTITUTE(_xlpm.Dim,"0,00","")&"m") ),"Ponte")} -> BTTC d= 1,00m
J28: *Condição de funcionamento: orifício
J29: *Carga hidráulica: h=1,2*H
J31: OBRA PROJETADA
J32: {=IFERROR(_xlfn.LET( _xlpm.Func,"Canal", _xlpm.Funcs,Base_Bueiros!$A$2:$A$37, _xlpm.Tipos,Base_Bueiros!$C$2:$C$37, _xlpm.Dims,Base_Bueiros!$D$2:$D$37, _xlpm.Vazoes,Base_Bueiros!$F$2:$F$37, _xlpm.DimNum,IFERROR(VALUE(TRIM(LEFT(_xlpm.Dims,FIND("x",_xlpm.Dims)-1))),VALUE(_xlpm.Dims)), _xlpm.Linhas,IF(MID(_xlpm.Tipos,2,1)="T",3,IF(MID(_xlpm.Tipos,2,1)="D",2,1)), _xlpm.EhTubular,MID(_xlpm.Tipos,3,1)="T", _xlpm.QNec,IF(ISNUMBER(FIND("Orif",_xlpm.Func)),IF(_xlpm.EhTubular,M22,M23),IF(_xlpm.EhTubular,M21,M22)), _xlpm.FiltroBase,(ISNUMBER(FIND(_xlpm.Func,_xlpm.Funcs)))*(_xlpm.Vazoes>=_xlpm.QNec), _xlpm.TemTubular,SUM(_xlpm.FiltroBase*_xlpm.EhTubular)>0, _xlpm.Filtro,_xlpm.FiltroBase*IF(_xlpm.TemTubular,_xlpm.EhTubular,NOT(_xlpm.EhTubular)), _xlpm.Prior1,IF(_xlpm.EhTubular,_xlpm.DimNum,_xlpm.Linhas), _xlpm.Prior2,IF(_xlpm.EhTubular,_xlpm.Linhas,_xlpm.DimNum), _xlpm.MenorPrior1,_xlfn.AGGREGATE(15,6,_xlpm.Prior1/_xlpm.Filtro,1), _xlpm.MenorPrior2,_xlfn.AGGREGATE(15,6,_xlpm.Prior2/(_xlpm.Filtro*(_xlpm.Prior1=_xlpm.MenorPrior1)),1), _xlpm.MenorVazao,_xlfn.AGGREGATE(15,6,_xlpm.Vazoes/(_xlpm.Filtro*(_xlpm.Prior1=_xlpm.MenorPrior1)*(_xlpm.Prior2=_xlpm.MenorPrior2)),1), _xlpm.Linha,MATCH(1,(_xlpm.Vazoes=_xlpm.MenorVazao)*(_xlpm.Filtro>0),0), _xlpm.Tipo,INDEX(_xlpm.Tipos,_xlpm.Linha), _xlpm.Dim,INDEX(_xlpm.Dims,_xlpm.Linha), _xlpm.EhTubularEscolhido,MID(_xlpm.Tipo,3,1)="T", _xlpm.Tipo&" "&IF(_xlpm.EhTubularEscolhido,_xlpm.Dim&"m",SUBSTITUTE(_xlpm.Dim,"0,00","")&"m") ),"Ponte")} -> BTTC d= 1,20m
J33: *Condição de funcionamento: canal
J35: OBRA EXISTENTE
J36: ='Apresentação - Est. Hid.'!AK20 -> -

Sheet PERFIL BC02
B2: Ponto | C2: Cota (m) | D2: Distância (m) | E2: Distância Acumulada (Km) | F2: DHn (m) | G2: DLn (km) | H2: Sn (m/km)
B3: C | C3: 668 | D3: 0 | E3: =D3/1000 -> 0 | F3: 0 | G3: 0 | H3: 0 | J3: Validação por macro
B4: 1 | C4: 667 | D4: 70 | E4: =D4/1000 -> 0.07 | F4: =C3-C4 -> 1 | G4: =E4-E3 -> 0.07 | H4: =F4/G4 -> 14.285714 | J4: Sef (m/km) | K4: =(((E10/((G4/SQRT(H4))+(G5/SQRT(H5))+(G6/SQRT(H6))+(G7/SQRT(H7))+(G8/SQRT(H8))+(G9/SQRT(H9))+(G10/SQRT(H10))))^2)/1000)*1000 -> 20.261343
B5: 2 | C5: 659 | D5: =D4+250 -> 320 | E5: =D5/1000 -> 0.32 | F5: =C4-C5 -> 8 | G5: =E5-E4 -> 0.25 | H5: =F5/G5 -> 32 | J5: Sef (m/m) | K5: =((E10/((G4/SQRT(H4))+(G5/SQRT(H5))+(G6/SQRT(H6))+(G7/SQRT(H7))+(G8/SQRT(H8))+(G9/SQRT(H9))+(G10/SQRT(H10))))^2)/1000 -> 0.020261343
B6: 3 | C6: 651 | D6: =D5+250 -> 570 | E6: =D6/1000 -> 0.57 | F6: =C5-C6 -> 8 | G6: =E6-E5 -> 0.25 | H6: =F6/G6 -> 32 | J6: Sef (%) | K6: =(((E10/((G4/SQRT(H4))+(G5/SQRT(H5))+(G6/SQRT(H6))+(G7/SQRT(H7))+(G8/SQRT(H8))+(G9/SQRT(H9))+(G10/SQRT(H10))))^2)/1000)*100 -> 2.0261343
B7: 4 | C7: 645 | D7: =D6+250 -> 820 | E7: =D7/1000 -> 0.82 | F7: =C6-C7 -> 6 | G7: =E7-E6 -> 0.25 | H7: =F7/G7 -> 24
B8: 5 | C8: 640 | D8: =D7+250 -> 1070 | E8: =D8/1000 -> 1.07 | F8: =C7-C8 -> 5 | G8: =E8-E7 -> 0.25 | H8: =F8/G8 -> 20
B9: 6 | C9: 637 | D9: =D8+250 -> 1320 | E9: =D9/1000 -> 1.32 | F9: =C8-C9 -> 3 | G9: =E9-E8 -> 0.25 | H9: =F9/G9 -> 12
B10: E | C10: 633 | D10: ='BC02 (RAC)'!E7*1000 -> 1571.8309 | E10: =D10/1000 -> 1.5718309 | F10: =C9-C10 -> 4 | G10: =E10-E9 -> 0.25183087 | H10: =F10/G10 -> 15.883677
B12: Sef = | C12: =(((E10/((G4/SQRT(H4))+(G5/SQRT(H5))+(G6/SQRT(H6))+(G7/SQRT(H7))+(G8/SQRT(H8))+(G9/SQRT(H9))+(G10/SQRT(H10))))^2)/1000)*1000 -> 20.261343 | D12: (m/km) | E12: m/km
B13: Sef = | C13: =C12/1000 -> 0.020261343 | D13: (m/m) | E13: m/m
B14: Sef = | C14: =C13*100 -> 2.0261343 | D14: (%) | E14: %
A34: ="Perfil Longitudinal - "&'BC02 (RAC)'!E5 -> Perfil Longitudinal - Sem talvegue permanente

Sheet BC03 (RAC-MOD)
A1: ESTUDOS HIDROLÓGICOS
A2: Método Racional Modificado
B3: Estaca: | E3: 148 | F3: + | G3: 7.27 | Q3: UTILIZAR TABELA QUADRO DE CHUVAS ISOZONAS DADOS PLUVIOMÉTRICOS
B4: VIA : | E4: GO-116 | F4: GROTA | K4: TEMPO DE RECORRÊNCIA : | N4: 15 | O4: anos
B5: CURSO D'ÁGUA : | E5: Córrego Taboca | K5: TEMPO DE RECORRÊNCIA : | N5: 25 | O5: anos | Q5: DECLIVIDADE EFETIVA (%): | R5: ='PERFIL BC03'!C16 -> 5.1960506
B6: ÁREA DE CONTRIBUIÇÃO (km²) : | E6: =VLOOKUP(F10,'AUX BACIAS'!$A$2:$D$10,3,0) -> 5.5221224 | K6: TEMPO DE RECORRÊNCIA : | N6: 50 | O6: anos | Q6: DECLIVIDADE MÉDIA (%): | R6: =100*(E8/(E7*1000)) -> 11.606984
B7: COMP. DO TALVEGUE (km) : | E7: =(VLOOKUP(F10,'AUX BACIAS'!$A$2:$D$10,4,0)/1000) -> 4.4800612 | K7: TEMPO DE RECORRÊNCIA : | N7: 100 | O7: anos
B8: DESNÍVEL (m) : | E8: =(INDEX('PERFIL BC03'!$C:$C,MATCH("C",'PERFIL BC03'!$B:$B,0))-INDEX('PERFIL BC03'!$C:$C,MATCH("E",'PERFIL BC03'!$B:$B,0))) -> 520 | K8: COEFICIENTE C: | O8: =H23 -> 0.35
B9: DECLIVIDADE DA BACIA (%) : | E9: =IF(R5>R6,R6,R5) -> 5.1960506 | K9: TEMPO DE CONCENTRAÇÃO Tc (h) : | O9: =IF(E6<=0.8,0.39*(E7^2/E9)^0.385,0.59*(E7^2/E9)^0.385) -> 0.99267345
E10: Nº Bacia: | F10: {=MID(RIGHT(CELL("nome.arquivo",A1),LEN(CELL("nome.arquivo",A1)) - SEARCH("]",CELL("nome.arquivo",A1))),1,4)} -> BC03 | K10: COEFICIENTE DE RETARDO (φ): | O10: =MAX(0.5,MIN(1,4.38/(E6^0.2*E7))) -> 0.69465467
B11: Tipo de Relevo | C11: =IF(E9<=2,"Plano",IF(AND(E9>2,E9<=5),"Levemente ondulado",IF(AND(E9>5,E9<=10),"Ondulado",IF(AND(E9>10,E9<=20),"Muito ondulado",IF(AND(E9>20,E9<=50),"Montanhoso",IF(AND(E9>50,E9<=100),"Muito montanhoso","Escarpado")))))) -> Ondulado
B12: Orografia | C12: B | J12: CHUVA DE PROJETO | Q12: Auxiliar - Não apagar
B13: * Classificação de orografia segundo a IP 03 – Goinfra – Estudos hidrológicos | J13: TR | K13: D tc (min) | L13: Po (mm) | N13: I (mm/min) | Q13: {=IFERROR(_xlfn.LET( _xlpm.Q,M20, _xlpm.Tipos,[3]Base_Bueiros!$C$2:$C$10, _xlpm.Dims,[3]Base_Bueiros!$D$2:$D$10, _xlpm.Vazoes,[3]Base_Bueiros!$F$2:$F$10, _xlpm.Diam,VALUE(_xlpm.Dims), _xlpm.MenorDiam,_xlfn.AGGREGATE(15,6,_xlpm.Diam/(_xlpm.Vazoes>=_xlpm.Q),1), _xlpm.MenorVazao,_xlfn.AGGREGATE(15,6,_xlpm.Vazoes/((_xlpm.Vazoes>=_xlpm.Q)*(_xlpm.Diam=_xlpm.MenorDiam)),1), _xlpm.Linha,MATCH(_xlpm.MenorVazao,_xlpm.Vazoes,0), INDEX(_xlpm.Tipos,_xlpm.Linha)&" d="&INDEX(_xlpm.Dims,_xlpm.Linha)&"m" ),"Não atende em canal 15 anos. Dimensionar para 25 anos")} -> Não atende em canal 15 anos. Dimensionar para 25 anos | S13: =IF(Q13="Não atende em canal 15 anos. Dimensionar para 25 anos",25,15) -> 25 | X13: ax | Y13: + | Z13: b | AB13: ='BC01 (RAC)'!AB13 -> ax (1-24h) | AC13: Método para C
J14: 15 anos | K14: =$O$9*60 -> 59.560407 | L14: =IF($O$9<=1,(X14*LN((K14/60)))+Z14,(AB14*LN((K14/60)))+Z14) -> 83.185525 | N14: =L14/K14 -> 1.3966581 | Q14: {=IFERROR(_xlfn.LET( _xlpm.Q,M21, _xlpm.Tipos,[3]Base_Bueiros!$C$20:$C$28, _xlpm.Dims,[3]Base_Bueiros!$D$20:$D$28, _xlpm.Vazoes,[3]Base_Bueiros!$F$20:$F$28, _xlpm.Diam,VALUE(_xlpm.Dims), _xlpm.MenorDiam,_xlfn.AGGREGATE(15,6,_xlpm.Diam/(_xlpm.Vazoes>=_xlpm.Q),1), _xlpm.MenorVazao,_xlfn.AGGREGATE(15,6,_xlpm.Vazoes/((_xlpm.Vazoes>=_xlpm.Q)*(_xlpm.Diam=_xlpm.MenorDiam)),1), _xlpm.Linha,MATCH(_xlpm.MenorVazao,_xlpm.Vazoes,0), _xlpm.Tipo,TRIM(IFERROR(LEFT(INDEX(_xlpm.Tipos,_xlpm.Linha),FIND(" OU ",INDEX(_xlpm.Tipos,_xlpm.Linha))-1),INDEX(_xlpm.Tipos,_xlpm.Linha))), _xlpm.Tipo&" d="&INDEX(_xlpm.Dims,_xlpm.Linha)&"m" ),"Não atende em orifício 25 anos. Dimensionar para 50 anos")} -> Não atende em orifício 25 anos. Dimensionar para 50 anos | S14: =IF(Q14="Não atende em orifício 25 anos. Dimensionar para 50 anos",50,25) -> 50 | X14: ='BC01 (RAC)'!X14 -> 26.41506 | Z14: ='BC01 (RAC)'!Z14 -> 83.379769 | AB14: ='BC01 (RAC)'!AB14 -> 24.188986 | AC14: =IF(C11="Plano","Tabelado",IF(C11="Ondulado","Tabelado",IF(C11="Montanhoso","Tabelado","Ponderado"))) -> Tabelado
J15: 25 anos | K15: =$O$9*60 -> 59.560407 | L15: =IF($O$9<=1,(X15*LN((K15/60)))+Z15,(AB15*LN((K15/60)))+Z15) -> 91.710848 | N15: =L15/K15 -> 1.5397955 | X15: ='BC01 (RAC)'!X15 -> 29.043207 | Z15: ='BC01 (RAC)'!Z15 -> 91.924418 | AB15: ='BC01 (RAC)'!AB15 -> 26.572791
J16: 50 anos | K16: =$O$9*60 -> 59.560407 | L16: =IF($O$9<=1,(X16*LN((K16/60)))+Z16,(AB16*LN((K16/60)))+Z16) -> 102.80742 | N16: =L16/K16 -> 1.7261034 | X16: ='BC01 (RAC)'!X16 -> 32.43716 | Z16: ='BC01 (RAC)'!Z16 -> 103.04595 | AB16: ='BC01 (RAC)'!AB16 -> 29.779923
J17: 100 anos | K17: =$O$9*60 -> 59.560407 | L17: =IF($O$9<=1,(X17*LN((K17/60)))+Z17,(AB17*LN((K17/60)))+Z17) -> 113.58236 | N17: =L17/K17 -> 1.9070111 | X17: ='BC01 (RAC)'!X17 -> 37.177213 | Z17: ='BC01 (RAC)'!Z17 -> 113.85574 | AB17: ='BC01 (RAC)'!AB17 -> 33.004345
B18: COMPOSIÇÃO DE ÁREA "C"
D19: m² | E19: km² | F19: C | G19: % | J19: Resultados | K19: Recorrência | M19: Qmáx
B20: Área total | D20: =E20*10^6 -> 5522122.4 | E20: =E6 -> 5.5221224 | F20: - | G20: - | H20: - | K20: Q15 = | M20: =0.278*$O$8*(N14*60)*$E$6*$O$10 -> 31.277295 | N20: m³/s
B21: Culturas e pastagens terraceadas | D21: =$D$20*G21 -> 3458505.3 | E21: =D21/10^6 -> 3.4585053 | F21: {=_xlfn.LET( _xlpm.superficie,B21, _xlpm.oro,$C$12, _xlpm.terreno,$C$11, _xlpm.metodo,$AC$14, _xlpm.linInicial,MATCH(_xlpm.superficie,C_CN_IP03!$B$4:$B$19,0), _xlpm.lin,_xlpm.linInicial+MATCH(_xlpm.oro,INDEX(C_CN_IP03!$C$4:$C$19,_xlpm.linInicial):INDEX(C_CN_IP03!$C$4:$C$19,_xlpm.linInicial+3),0)-1, IF( _xlpm.metodo="Tabelado", _xlfn.LET( _xlpm.col,MATCH(_xlpm.terreno,C_CN_IP03!$D$2:$I$2,0), INDEX(C_CN_IP03!$D$4:$I$19,_xlpm.lin,_xlpm.col) ), IF( _xlpm.metodo="Ponderado", IF( _xlpm.terreno="Levemente ondulado", AVERAGE( INDEX(C_CN_IP03!$D$4:$I$19,_xlpm.lin,1), INDEX(C_CN_IP03!$D$4:$I$19,_xlpm.lin,3) ), IF( _xlpm.terreno="Muito ondulado", AVERAGE( INDEX(C_CN_IP03!$D$4:$I$19,_xlpm.lin,3), INDEX(C_CN_IP03!$D$4:$I$19,_xlpm.lin,5) ), "Condição de terreno não reconhecida" ) ), "Método não reconhecido" ) ) )} -> 0.35 | G21: 0.6263 | H21: =(G21*(F21)) -> 0.219205 | K21: Q25 = | M21: =0.278*$O$8*(N15*60)*$E$6*$O$10 -> 34.482769 | N21: m³/s
B22: Cerrados, pastagens e matas ralas | D22: =$D$20*G22 -> 2063617.1 | E22: =D22*(10^-6) -> 2.0636171 | F22: {=_xlfn.LET( _xlpm.superficie,B22, _xlpm.oro,$C$12, _xlpm.terreno,$C$11, _xlpm.metodo,$AC$14, _xlpm.linInicial,MATCH(_xlpm.superficie,C_CN_IP03!$B$4:$B$19,0), _xlpm.lin,_xlpm.linInicial+MATCH(_xlpm.oro,INDEX(C_CN_IP03!$C$4:$C$19,_xlpm.linInicial):INDEX(C_CN_IP03!$C$4:$C$19,_xlpm.linInicial+3),0)-1, IF( _xlpm.metodo="Tabelado", _xlfn.LET( _xlpm.col,MATCH(_xlpm.terreno,C_CN_IP03!$D$2:$I$2,0), INDEX(C_CN_IP03!$D$4:$I$19,_xlpm.lin,_xlpm.col) ), IF( _xlpm.metodo="Ponderado", IF( _xlpm.terreno="Levemente ondulado", AVERAGE( INDEX(C_CN_IP03!$D$4:$I$19,_xlpm.lin,1), INDEX(C_CN_IP03!$D$4:$I$19,_xlpm.lin,3) ), IF( _xlpm.terreno="Muito ondulado", AVERAGE( INDEX(C_CN_IP03!$D$4:$I$19,_xlpm.lin,3), INDEX(C_CN_IP03!$D$4:$I$19,_xlpm.lin,5) ), "Condição de terreno não reconhecida" ) ), "Método não reconhecido" ) ) )} -> 0.35 | G22: 0.3737 | H22: =(G22*(F22)) -> 0.130795 | K22: Q50 = | M22: =0.278*$O$8*(N16*60)*$E$6*$O$10 -> 38.655017 | N22: m³/s
B23: C adotado | H23: =_xlfn.CEILING.MATH(SUM(H21:H22),0.05) -> 0.35 | K23: Q100 = | M23: =0.278*$O$8*(N17*60)*$E$6*$O$10 -> 42.706334 | N23: m³/s
B24: * Tabela de coeficientes de C e CN - IP 03 – Goinfra – Estudos hidrológicos
J25: OBRA PROJETADA
J26: {=IFERROR(_xlfn.LET( _xlpm.Func,"Orif", _xlpm.Funcs,Base_Bueiros!$A$2:$A$37, _xlpm.Tipos,Base_Bueiros!$C$2:$C$37, _xlpm.Dims,Base_Bueiros!$D$2:$D$37, _xlpm.Vazoes,Base_Bueiros!$F$2:$F$37, _xlpm.DimNum,IFERROR(VALUE(TRIM(LEFT(_xlpm.Dims,FIND("x",_xlpm.Dims)-1))),VALUE(_xlpm.Dims)), _xlpm.Linhas,IF(MID(_xlpm.Tipos,2,1)="T",3,IF(MID(_xlpm.Tipos,2,1)="D",2,1)), _xlpm.EhTubular,MID(_xlpm.Tipos,3,1)="T", _xlpm.QNec,IF(ISNUMBER(FIND("Orif",_xlpm.Func)),IF(_xlpm.EhTubular,M21,M22),IF(_xlpm.EhTubular,M20,M21)), _xlpm.FiltroBase,(ISNUMBER(FIND(_xlpm.Func,_xlpm.Funcs)))*(_xlpm.Vazoes>=_xlpm.QNec), _xlpm.TemTubular,SUM(_xlpm.FiltroBase*_xlpm.EhTubular)>0, _xlpm.Filtro,_xlpm.FiltroBase*IF(_xlpm.TemTubular,_xlpm.EhTubular,NOT(_xlpm.EhTubular)), _xlpm.Prior1,IF(_xlpm.EhTubular,_xlpm.DimNum,_xlpm.Linhas), _xlpm.Prior2,IF(_xlpm.EhTubular,_xlpm.Linhas,_xlpm.DimNum), _xlpm.MenorPrior1,_xlfn.AGGREGATE(15,6,_xlpm.Prior1/_xlpm.Filtro,1), _xlpm.MenorPrior2,_xlfn.AGGREGATE(15,6,_xlpm.Prior2/(_xlpm.Filtro*(_xlpm.Prior1=_xlpm.MenorPrior1)),1), _xlpm.MenorVazao,_xlfn.AGGREGATE(15,6,_xlpm.Vazoes/(_xlpm.Filtro*(_xlpm.Prior1=_xlpm.MenorPrior1)*(_xlpm.Prior2=_xlpm.MenorPrior2)),1), _xlpm.Linha,MATCH(1,(_xlpm.Vazoes=_xlpm.MenorVazao)*(_xlpm.Filtro>0),0), _xlpm.Tipo,INDEX(_xlpm.Tipos,_xlpm.Linha), _xlpm.Dim,INDEX(_xlpm.Dims,_xlpm.Linha), _xlpm.EhTubularEscolhido,MID(_xlpm.Tipo,3,1)="T", _xlpm.Tipo&" "&IF(_xlpm.EhTubularEscolhido,_xlpm.Dim&"m",SUBSTITUTE(_xlpm.Dim,"0,00","")&"m") ),"Ponte")} -> BSCC 3,00 x 3,00m
J27: *Condição de funcionamento: orifício
J28: *Carga hidráulica: h=1,2*H
J30: OBRA PROJETADA
J31: {=IFERROR(_xlfn.LET( _xlpm.Func,"Canal", _xlpm.Funcs,Base_Bueiros!$A$2:$A$37, _xlpm.Tipos,Base_Bueiros!$C$2:$C$37, _xlpm.Dims,Base_Bueiros!$D$2:$D$37, _xlpm.Vazoes,Base_Bueiros!$F$2:$F$37, _xlpm.DimNum,IFERROR(VALUE(TRIM(LEFT(_xlpm.Dims,FIND("x",_xlpm.Dims)-1))),VALUE(_xlpm.Dims)), _xlpm.Linhas,IF(MID(_xlpm.Tipos,2,1)="T",3,IF(MID(_xlpm.Tipos,2,1)="D",2,1)), _xlpm.EhTubular,MID(_xlpm.Tipos,3,1)="T", _xlpm.QNec,IF(ISNUMBER(FIND("Orif",_xlpm.Func)),IF(_xlpm.EhTubular,M21,M22),IF(_xlpm.EhTubular,M20,M21)), _xlpm.FiltroBase,(ISNUMBER(FIND(_xlpm.Func,_xlpm.Funcs)))*(_xlpm.Vazoes>=_xlpm.QNec), _xlpm.TemTubular,SUM(_xlpm.FiltroBase*_xlpm.EhTubular)>0, _xlpm.Filtro,_xlpm.FiltroBase*IF(_xlpm.TemTubular,_xlpm.EhTubular,NOT(_xlpm.EhTubular)), _xlpm.Prior1,IF(_xlpm.EhTubular,_xlpm.DimNum,_xlpm.Linhas), _xlpm.Prior2,IF(_xlpm.EhTubular,_xlpm.Linhas,_xlpm.DimNum), _xlpm.MenorPrior1,_xlfn.AGGREGATE(15,6,_xlpm.Prior1/_xlpm.Filtro,1), _xlpm.MenorPrior2,_xlfn.AGGREGATE(15,6,_xlpm.Prior2/(_xlpm.Filtro*(_xlpm.Prior1=_xlpm.MenorPrior1)),1), _xlpm.MenorVazao,_xlfn.AGGREGATE(15,6,_xlpm.Vazoes/(_xlpm.Filtro*(_xlpm.Prior1=_xlpm.MenorPrior1)*(_xlpm.Prior2=_xlpm.MenorPrior2)),1), _xlpm.Linha,MATCH(1,(_xlpm.Vazoes=_xlpm.MenorVazao)*(_xlpm.Filtro>0),0), _xlpm.Tipo,INDEX(_xlpm.Tipos,_xlpm.Linha), _xlpm.Dim,INDEX(_xlpm.Dims,_xlpm.Linha), _xlpm.EhTubularEscolhido,MID(_xlpm.Tipo,3,1)="T", _xlpm.Tipo&" "&IF(_xlpm.EhTubularEscolhido,_xlpm.Dim&"m",SUBSTITUTE(_xlpm.Dim,"0,00","")&"m") ),"Ponte")} -> BDCC 3,00 x 3,00m
J32: *Condição de funcionamento: canal
J34: OBRA EXISTENTE
J35: ='Apresentação - Est. Hid.'!AK21 -> Ponte existente 9,50x4,00m

Sheet PERFIL BC03
B2: Ponto | C2: Cota (m) | D2: Distância (m) | E2: Distância Acumulada (Km) | F2: DHn (m) | G2: DLn (km) | H2: Sn (m/km)
B3: C | C3: 1164 | D3: 0 | E3: =D3/1000 -> 0 | F3: 0 | G3: 0 | H3: 0 | J3: Validação por macro
B4: 2 | C4: 944 | D4: 500 | E4: =D4/1000 -> 0.5 | F4: =C3-C4 -> 220 | G4: =E4-E3 -> 0.5 | H4: =F4/G4 -> 440 | J4: Sef (m/km) | K4: =(((E12/((G4/SQRT(H4))+(G5/SQRT(H5))+(G6/SQRT(H6))+(G7/SQRT(H7))+(G8/SQRT(H8))+(G9/SQRT(H9))+(G10/SQRT(H10))+(G11/SQRT(H11))+(G12/SQRT(H12))))^2)/1000)*1000 -> 51.960506
B5: 3 | C5: 843 | D5: =D4+500 -> 1000 | E5: =D5/1000 -> 1 | F5: =C4-C5 -> 101 | G5: =E5-E4 -> 0.5 | H5: =F5/G5 -> 202 | J5: Sef (m/m) | K5: =((E12/((G4/SQRT(H4))+(G5/SQRT(H5))+(G6/SQRT(H6))+(G7/SQRT(H7))+(G8/SQRT(H8))+(G9/SQRT(H9))+(G10/SQRT(H10))+(G11/SQRT(H11))+(G12/SQRT(H12))))^2)/1000 -> 0.051960506
B6: 4 | C6: 766 | D6: =D5+500 -> 1500 | E6: =D6/1000 -> 1.5 | F6: =C5-C6 -> 77 | G6: =E6-E5 -> 0.5 | H6: =F6/G6 -> 154 | J6: Sef (%) | K6: =(((E12/((G4/SQRT(H4))+(G5/SQRT(H5))+(G6/SQRT(H6))+(G7/SQRT(H7))+(G8/SQRT(H8))+(G9/SQRT(H9))+(G10/SQRT(H10))+(G11/SQRT(H11))+(G12/SQRT(H12))))^2)/1000)*100 -> 5.1960506
B7: 5 | C7: 721 | D7: =D6+500 -> 2000 | E7: =D7/1000 -> 2 | F7: =C6-C7 -> 45 | G7: =E7-E6 -> 0.5 | H7: =F7/G7 -> 90
B8: 6 | C8: 695 | D8: =D7+500 -> 2500 | E8: =D8/1000 -> 2.5 | F8: =C7-C8 -> 26 | G8: =E8-E7 -> 0.5 | H8: =F8/G8 -> 52
B9: 7 | C9: 676 | D9: =D8+500 -> 3000 | E9: =D9/1000 -> 3 | F9: =C8-C9 -> 19 | G9: =E9-E8 -> 0.5 | H9: =F9/G9 -> 38
B10: 8 | C10: 664 | D10: =D9+500 -> 3500 | E10: =D10/1000 -> 3.5 | F10: =C9-C10 -> 12 | G10: =E10-E9 -> 0.5 | H10: =F10/G10 -> 24
B11: 9 | C11: 654 | D11: =D10+500 -> 4000 | E11: =D11/1000 -> 4 | F11: =C10-C11 -> 10 | G11: =E11-E10 -> 0.5 | H11: =F11/G11 -> 20
B12: E | C12: 644 | D12: ='BC03 (RAC-MOD)'!E7*1000 -> 4480.0612 | E12: =D12/1000 -> 4.4800612 | F12: =C11-C12 -> 10 | G12: =E12-E11 -> 0.48006121 | H12: =F12/G12 -> 20.830677
B14: Sef = | C14: =(((E12/((G4/SQRT(H4))+(G5/SQRT(H5))+(G6/SQRT(H6))+(G7/SQRT(H7))+(G8/SQRT(H8))+(G9/SQRT(H9))+(G10/SQRT(H10))+(G11/SQRT(H11))+(G12/SQRT(H12))))^2)/1000)*1000 -> 51.960506 | D14: (m/km) | E14: m/km
B15: Sef = | C15: =C14/1000 -> 0.051960506 | D15: (m/m) | E15: m/m
B16: Sef = | C16: =C15*100 -> 5.1960506 | D16: (%) | E16: %

Sheet BC04 (RAC-MOD)
A1: ESTUDOS HIDROLÓGICOS
A2: Método Racional Modificado
B3: Estaca: | E3: 214 | F3: + | G3: 13.34 | Q3: UTILIZAR TABELA QUADRO DE CHUVAS ISOZONAS DADOS PLUVIOMÉTRICOS
B4: VIA : | E4: GO-116 | F4: GROTA | K4: TEMPO DE RECORRÊNCIA : | N4: 15 | O4: anos
B5: CURSO D'ÁGUA : | E5: Córrego Jacu | K5: TEMPO DE RECORRÊNCIA : | N5: 25 | O5: anos | Q5: DECLIVIDADE EFETIVA (%): | R5: ='PERFIL BC04'!C16 -> 3.1404046
B6: ÁREA DE CONTRIBUIÇÃO (km²) : | E6: =VLOOKUP(F10,'AUX BACIAS'!$A$2:$D$10,3,0) -> 5.0371131 | K6: TEMPO DE RECORRÊNCIA : | N6: 50 | O6: anos | Q6: DECLIVIDADE MÉDIA (%): | R6: =100*(E8/(E7*1000)) -> 11.19832
B7: COMP. DO TALVEGUE (km) : | E7: =(VLOOKUP(F10,'AUX BACIAS'!$A$2:$D$10,4,0)/1000) -> 4.4738852 | K7: TEMPO DE RECORRÊNCIA : | N7: 100 | O7: anos
B8: DESNÍVEL (m) : | E8: =(INDEX('PERFIL BC04'!$C:$C,MATCH("C",'PERFIL BC04'!$B:$B,0))-INDEX('PERFIL BC04'!$C:$C,MATCH("E",'PERFIL BC04'!$B:$B,0))) -> 501 | K8: COEFICIENTE C: | O8: =H23 -> 0.35
B9: DECLIVIDADE DA BACIA (%) : | E9: =IF(R5>R6,R6,R5) -> 3.1404046 | K9: TEMPO DE CONCENTRAÇÃO Tc (h) : | O9: =IF(E6<=0.8,0.39*(E7^2/E9)^0.385,0.59*(E7^2/E9)^0.385) -> 1.2037599
E10: Nº Bacia: | F10: {=MID(RIGHT(CELL("nome.arquivo",A1),LEN(CELL("nome.arquivo",A1)) - SEARCH("]",CELL("nome.arquivo",A1))),1,4)} -> BC04 | K10: COEFICIENTE DE RETARDO (φ): | O10: =MAX(0.5,MIN(1,4.38/(E6^0.2*E7))) -> 0.70852134
B11: Tipo de Relevo | C11: Ondulado
B12: Orografia | C12: B | J12: CHUVA DE PROJETO | Q12: Auxiliar - Não apagar
B13: * Classificação de orografia segundo a IP 03 – Goinfra – Estudos hidrológicos | J13: TR | K13: D tc (min) | L13: Po (mm) | N13: I (mm/min) | Q13: {=IFERROR(_xlfn.LET( _xlpm.Q,M20, _xlpm.Tipos,[3]Base_Bueiros!$C$2:$C$10, _xlpm.Dims,[3]Base_Bueiros!$D$2:$D$10, _xlpm.Vazoes,[3]Base_Bueiros!$F$2:$F$10, _xlpm.Diam,VALUE(_xlpm.Dims), _xlpm.MenorDiam,_xlfn.AGGREGATE(15,6,_xlpm.Diam/(_xlpm.Vazoes>=_xlpm.Q),1), _xlpm.MenorVazao,_xlfn.AGGREGATE(15,6,_xlpm.Vazoes/((_xlpm.Vazoes>=_xlpm.Q)*(_xlpm.Diam=_xlpm.MenorDiam)),1), _xlpm.Linha,MATCH(_xlpm.MenorVazao,_xlpm.Vazoes,0), INDEX(_xlpm.Tipos,_xlpm.Linha)&" d="&INDEX(_xlpm.Dims,_xlpm.Linha)&"m" ),"Não atende em canal 15 anos. Dimensionar para 25 anos")} -> Não atende em canal 15 anos. Dimensionar para 25 anos | S13: =IF(Q13="Não atende em canal 15 anos. Dimensionar para 25 anos",25,15) -> 25 | X13: ax | Y13: + | Z13: b | AB13: ='BC01 (RAC)'!AB13 -> ax (1-24h) | AC13: Método para C
J14: 15 anos | K14: =$O$9*60 -> 72.225595 | L14: =IF($O$9<=1,(X14*LN((K14/60)))+Z14,(AB14*LN((K14/60)))+Z14) -> 87.865614 | N14: =L14/K14 -> 1.216544 | Q14: {=IFERROR(_xlfn.LET( _xlpm.Q,M21, _xlpm.Tipos,[3]Base_Bueiros!$C$20:$C$28, _xlpm.Dims,[3]Base_Bueiros!$D$20:$D$28, _xlpm.Vazoes,[3]Base_Bueiros!$F$20:$F$28, _xlpm.Diam,VALUE(_xlpm.Dims), _xlpm.MenorDiam,_xlfn.AGGREGATE(15,6,_xlpm.Diam/(_xlpm.Vazoes>=_xlpm.Q),1), _xlpm.MenorVazao,_xlfn.AGGREGATE(15,6,_xlpm.Vazoes/((_xlpm.Vazoes>=_xlpm.Q)*(_xlpm.Diam=_xlpm.MenorDiam)),1), _xlpm.Linha,MATCH(_xlpm.MenorVazao,_xlpm.Vazoes,0), _xlpm.Tipo,TRIM(IFERROR(LEFT(INDEX(_xlpm.Tipos,_xlpm.Linha),FIND(" OU ",INDEX(_xlpm.Tipos,_xlpm.Linha))-1),INDEX(_xlpm.Tipos,_xlpm.Linha))), _xlpm.Tipo&" d="&INDEX(_xlpm.Dims,_xlpm.Linha)&"m" ),"Não atende em orifício 25 anos. Dimensionar para 50 anos")} -> Não atende em orifício 25 anos. Dimensionar para 50 anos | S14: =IF(Q14="Não atende em orifício 25 anos. Dimensionar para 50 anos",50,25) -> 50 | X14: ='BC01 (RAC)'!X14 -> 26.41506 | Z14: ='BC01 (RAC)'!Z14 -> 83.379769 | AB14: ='BC01 (RAC)'!AB14 -> 24.188986 | AC14: =IF(C11="Plano","Tabelado",IF(C11="Ondulado","Tabelado",IF(C11="Montanhoso","Tabelado","Ponderado"))) -> Tabelado
J15: 25 anos | K15: =$O$9*60 -> 72.225595 | L15: =IF($O$9<=1,(X15*LN((K15/60)))+Z15,(AB15*LN((K15/60)))+Z15) -> 96.85234 | N15: =L15/K15 -> 1.3409698 | X15: ='BC01 (RAC)'!X15 -> 29.043207 | Z15: ='BC01 (RAC)'!Z15 -> 91.924418 | AB15: ='BC01 (RAC)'!AB15 -> 26.572791
J16: 50 anos | K16: =$O$9*60 -> 72.225595 | L16: =IF($O$9<=1,(X16*LN((K16/60)))+Z16,(AB16*LN((K16/60)))+Z16) -> 108.56863 | N16: =L16/K16 -> 1.5031878 | X16: ='BC01 (RAC)'!X16 -> 32.43716 | Z16: ='BC01 (RAC)'!Z16 -> 103.04595 | AB16: ='BC01 (RAC)'!AB16 -> 29.779923
J17: 100 anos | K17: =$O$9*60 -> 72.225595 | L17: =IF($O$9<=1,(X17*LN((K17/60)))+Z17,(AB17*LN((K17/60)))+Z17) -> 119.97639 | N17: =L17/K17 -> 1.661134 | X17: ='BC01 (RAC)'!X17 -> 37.177213 | Z17: ='BC01 (RAC)'!Z17 -> 113.85574 | AB17: ='BC01 (RAC)'!AB17 -> 33.004345
B18: COMPOSIÇÃO DE ÁREA "C"
D19: m² | E19: km² | F19: C | G19: % | J19: Resultados | K19: Recorrência | M19: Qmáx
B20: Área total | D20: =E20*10^6 -> 5037113.1 | E20: =E6 -> 5.0371131 | F20: - | G20: - | H20: - | K20: Q15 = | M20: =0.278*$O$8*(N14*60)*$E$6*$O$10 -> 25.346999 | N20: m³/s
B21: Culturas e pastagens terraceadas | D21: =$D$20*G21 -> 2318079.5 | E21: =D21/10^6 -> 2.3180795 | F21: {=_xlfn.LET( _xlpm.superficie,B21, _xlpm.oro,$C$12, _xlpm.terreno,$C$11, _xlpm.metodo,$AC$14, _xlpm.linInicial,MATCH(_xlpm.superficie,C_CN_IP03!$B$4:$B$19,0), _xlpm.lin,_xlpm.linInicial+MATCH(_xlpm.oro,INDEX(C_CN_IP03!$C$4:$C$19,_xlpm.linInicial):INDEX(C_CN_IP03!$C$4:$C$19,_xlpm.linInicial+3),0)-1, IF( _xlpm.metodo="Tabelado", _xlfn.LET( _xlpm.col,MATCH(_xlpm.terreno,C_CN_IP03!$D$2:$I$2,0), INDEX(C_CN_IP03!$D$4:$I$19,_xlpm.lin,_xlpm.col) ), IF( _xlpm.metodo="Ponderado", IF( _xlpm.terreno="Levemente ondulado", AVERAGE( INDEX(C_CN_IP03!$D$4:$I$19,_xlpm.lin,1), INDEX(C_CN_IP03!$D$4:$I$19,_xlpm.lin,3) ), IF( _xlpm.terreno="Muito ondulado", AVERAGE( INDEX(C_CN_IP03!$D$4:$I$19,_xlpm.lin,3), INDEX(C_CN_IP03!$D$4:$I$19,_xlpm.lin,5) ), "Condição de terreno não reconhecida" ) ), "Método não reconhecido" ) ) )} -> 0.35 | G21: 0.4602 | H21: =(G21*(F21)) -> 0.16107 | K21: Q25 = | M21: =0.278*$O$8*(N15*60)*$E$6*$O$10 -> 27.939441 | N21: m³/s
B22: Cerrados, pastagens e matas ralas | D22: =$D$20*G22 -> 2719033.7 | E22: =D22*(10^-6) -> 2.7190337 | F22: {=_xlfn.LET( _xlpm.superficie,B22, _xlpm.oro,$C$12, _xlpm.terreno,$C$11, _xlpm.metodo,$AC$14, _xlpm.linInicial,MATCH(_xlpm.superficie,C_CN_IP03!$B$4:$B$19,0), _xlpm.lin,_xlpm.linInicial+MATCH(_xlpm.oro,INDEX(C_CN_IP03!$C$4:$C$19,_xlpm.linInicial):INDEX(C_CN_IP03!$C$4:$C$19,_xlpm.linInicial+3),0)-1, IF( _xlpm.metodo="Tabelado", _xlfn.LET( _xlpm.col,MATCH(_xlpm.terreno,C_CN_IP03!$D$2:$I$2,0), INDEX(C_CN_IP03!$D$4:$I$19,_xlpm.lin,_xlpm.col) ), IF( _xlpm.metodo="Ponderado", IF( _xlpm.terreno="Levemente ondulado", AVERAGE( INDEX(C_CN_IP03!$D$4:$I$19,_xlpm.lin,1), INDEX(C_CN_IP03!$D$4:$I$19,_xlpm.lin,3) ), IF( _xlpm.terreno="Muito ondulado", AVERAGE( INDEX(C_CN_IP03!$D$4:$I$19,_xlpm.lin,3), INDEX(C_CN_IP03!$D$4:$I$19,_xlpm.lin,5) ), "Condição de terreno não reconhecida" ) ), "Método não reconhecido" ) ) )} -> 0.35 | G22: 0.5398 | H22: =(G22*(F22)) -> 0.18893 | K22: Q50 = | M22: =0.278*$O$8*(N16*60)*$E$6*$O$10 -> 31.319294 | N22: m³/s
B23: C adotado | H23: =_xlfn.CEILING.MATH(SUM(H21:H22),0.05) -> 0.35 | K23: Q100 = | M23: =0.278*$O$8*(N17*60)*$E$6*$O$10 -> 34.610144 | N23: m³/s
B24: * Tabela de coeficientes de C e CN - IP 03 – Goinfra – Estudos hidrológicos
J25: OBRA PROJETADA
J26: {=IFERROR(_xlfn.LET( _xlpm.Func,"Orif", _xlpm.Funcs,Base_Bueiros!$A$2:$A$37, _xlpm.Tipos,Base_Bueiros!$C$2:$C$37, _xlpm.Dims,Base_Bueiros!$D$2:$D$37, _xlpm.Vazoes,Base_Bueiros!$F$2:$F$37, _xlpm.DimNum,IFERROR(VALUE(TRIM(LEFT(_xlpm.Dims,FIND("x",_xlpm.Dims)-1))),VALUE(_xlpm.Dims)), _xlpm.Linhas,IF(MID(_xlpm.Tipos,2,1)="T",3,IF(MID(_xlpm.Tipos,2,1)="D",2,1)), _xlpm.EhTubular,MID(_xlpm.Tipos,3,1)="T", _xlpm.QNec,IF(ISNUMBER(FIND("Orif",_xlpm.Func)),IF(_xlpm.EhTubular,M21,M22),IF(_xlpm.EhTubular,M20,M21)), _xlpm.FiltroBase,(ISNUMBER(FIND(_xlpm.Func,_xlpm.Funcs)))*(_xlpm.Vazoes>=_xlpm.QNec), _xlpm.TemTubular,SUM(_xlpm.FiltroBase*_xlpm.EhTubular)>0, _xlpm.Filtro,_xlpm.FiltroBase*IF(_xlpm.TemTubular,_xlpm.EhTubular,NOT(_xlpm.EhTubular)), _xlpm.Prior1,IF(_xlpm.EhTubular,_xlpm.DimNum,_xlpm.Linhas), _xlpm.Prior2,IF(_xlpm.EhTubular,_xlpm.Linhas,_xlpm.DimNum), _xlpm.MenorPrior1,_xlfn.AGGREGATE(15,6,_xlpm.Prior1/_xlpm.Filtro,1), _xlpm.MenorPrior2,_xlfn.AGGREGATE(15,6,_xlpm.Prior2/(_xlpm.Filtro*(_xlpm.Prior1=_xlpm.MenorPrior1)),1), _xlpm.MenorVazao,_xlfn.AGGREGATE(15,6,_xlpm.Vazoes/(_xlpm.Filtro*(_xlpm.Prior1=_xlpm.MenorPrior1)*(_xlpm.Prior2=_xlpm.MenorPrior2)),1), _xlpm.Linha,MATCH(1,(_xlpm.Vazoes=_xlpm.MenorVazao)*(_xlpm.Filtro>0),0), _xlpm.Tipo,INDEX(_xlpm.Tipos,_xlpm.Linha), _xlpm.Dim,INDEX(_xlpm.Dims,_xlpm.Linha), _xlpm.EhTubularEscolhido,MID(_xlpm.Tipo,3,1)="T", _xlpm.Tipo&" "&IF(_xlpm.EhTubularEscolhido,_xlpm.Dim&"m",SUBSTITUTE(_xlpm.Dim,"0,00","")&"m") ),"Ponte")} -> BSCC 3,00 x 3,00m
J27: *Condição de funcionamento: orifício
J28: *Carga hidráulica: h=1,2*H
J30: OBRA PROJETADA
J31: {=IFERROR(_xlfn.LET( _xlpm.Func,"Canal", _xlpm.Funcs,Base_Bueiros!$A$2:$A$37, _xlpm.Tipos,Base_Bueiros!$C$2:$C$37, _xlpm.Dims,Base_Bueiros!$D$2:$D$37, _xlpm.Vazoes,Base_Bueiros!$F$2:$F$37, _xlpm.DimNum,IFERROR(VALUE(TRIM(LEFT(_xlpm.Dims,FIND("x",_xlpm.Dims)-1))),VALUE(_xlpm.Dims)), _xlpm.Linhas,IF(MID(_xlpm.Tipos,2,1)="T",3,IF(MID(_xlpm.Tipos,2,1)="D",2,1)), _xlpm.EhTubular,MID(_xlpm.Tipos,3,1)="T", _xlpm.QNec,IF(ISNUMBER(FIND("Orif",_xlpm.Func)),IF(_xlpm.EhTubular,M21,M22),IF(_xlpm.EhTubular,M20,M21)), _xlpm.FiltroBase,(ISNUMBER(FIND(_xlpm.Func,_xlpm.Funcs)))*(_xlpm.Vazoes>=_xlpm.QNec), _xlpm.TemTubular,SUM(_xlpm.FiltroBase*_xlpm.EhTubular)>0, _xlpm.Filtro,_xlpm.FiltroBase*IF(_xlpm.TemTubular,_xlpm.EhTubular,NOT(_xlpm.EhTubular)), _xlpm.Prior1,IF(_xlpm.EhTubular,_xlpm.DimNum,_xlpm.Linhas), _xlpm.Prior2,IF(_xlpm.EhTubular,_xlpm.Linhas,_xlpm.DimNum), _xlpm.MenorPrior1,_xlfn.AGGREGATE(15,6,_xlpm.Prior1/_xlpm.Filtro,1), _xlpm.MenorPrior2,_xlfn.AGGREGATE(15,6,_xlpm.Prior2/(_xlpm.Filtro*(_xlpm.Prior1=_xlpm.MenorPrior1)),1), _xlpm.MenorVazao,_xlfn.AGGREGATE(15,6,_xlpm.Vazoes/(_xlpm.Filtro*(_xlpm.Prior1=_xlpm.MenorPrior1)*(_xlpm.Prior2=_xlpm.MenorPrior2)),1), _xlpm.Linha,MATCH(1,(_xlpm.Vazoes=_xlpm.MenorVazao)*(_xlpm.Filtro>0),0), _xlpm.Tipo,INDEX(_xlpm.Tipos,_xlpm.Linha), _xlpm.Dim,INDEX(_xlpm.Dims,_xlpm.Linha), _xlpm.EhTubularEscolhido,MID(_xlpm.Tipo,3,1)="T", _xlpm.Tipo&" "&IF(_xlpm.EhTubularEscolhido,_xlpm.Dim&"m",SUBSTITUTE(_xlpm.Dim,"0,00","")&"m") ),"Ponte")} -> BDCC 2,50 x 2,50m
J32: *Condição de funcionamento: canal
J34: OBRA EXISTENTE
J35: ='Apresentação - Est. Hid.'!AK22 -> Ponte existente 15,00x3,90m

Sheet PERFIL BC04
B2: Ponto | C2: Cota (m) | D2: Distância (m) | E2: Distância Acumulada (Km) | F2: DHn (m) | G2: DLn (km) | H2: Sn (m/km)
B3: C | C3: 1135 | D3: 0 | E3: =D3/1000 -> 0 | F3: 0 | G3: 0 | H3: 0 | J3: Validação por macro
B4: 2 | C4: 876 | D4: 500 | E4: =D4/1000 -> 0.5 | F4: =C3-C4 -> 259 | G4: =E4-E3 -> 0.5 | H4: =F4/G4 -> 518 | J4: Sef (m/km) | K4: =(((E12/((G4/SQRT(H4))+(G5/SQRT(H5))+(G6/SQRT(H6))+(G7/SQRT(H7))+(G8/SQRT(H8))+(G9/SQRT(H9))+(G10/SQRT(H10))+(G11/SQRT(H11))+(G12/SQRT(H12))))^2)/1000)*1000 -> 31.404046
B5: 3 | C5: 772 | D5: =D4+500 -> 1000 | E5: =D5/1000 -> 1 | F5: =C4-C5 -> 104 | G5: =E5-E4 -> 0.5 | H5: =F5/G5 -> 208 | J5: Sef (m/m) | K5: =((E12/((G4/SQRT(H4))+(G5/SQRT(H5))+(G6/SQRT(H6))+(G7/SQRT(H7))+(G8/SQRT(H8))+(G9/SQRT(H9))+(G10/SQRT(H10))+(G11/SQRT(H11))+(G12/SQRT(H12))))^2)/1000 -> 0.031404046
B6: 4 | C6: 725 | D6: =D5+500 -> 1500 | E6: =D6/1000 -> 1.5 | F6: =C5-C6 -> 47 | G6: =E6-E5 -> 0.5 | H6: =F6/G6 -> 94 | J6: Sef (%) | K6: =(((E12/((G4/SQRT(H4))+(G5/SQRT(H5))+(G6/SQRT(H6))+(G7/SQRT(H7))+(G8/SQRT(H8))+(G9/SQRT(H9))+(G10/SQRT(H10))+(G11/SQRT(H11))+(G12/SQRT(H12))))^2)/1000)*100 -> 3.1404046
B7: 5 | C7: 688 | D7: =D6+500 -> 2000 | E7: =D7/1000 -> 2 | F7: =C6-C7 -> 37 | G7: =E7-E6 -> 0.5 | H7: =F7/G7 -> 74
B8: 6 | C8: 667 | D8: =D7+500 -> 2500 | E8: =D8/1000 -> 2.5 | F8: =C7-C8 -> 21 | G8: =E8-E7 -> 0.5 | H8: =F8/G8 -> 42
B9: 7 | C9: 652 | D9: =D8+500 -> 3000 | E9: =D9/1000 -> 3 | F9: =C8-C9 -> 15 | G9: =E9-E8 -> 0.5 | H9: =F9/G9 -> 30
B10: 8 | C10: 649 | D10: =D9+500 -> 3500 | E10: =D10/1000 -> 3.5 | F10: =C9-C10 -> 3 | G10: =E10-E9 -> 0.5 | H10: =F10/G10 -> 6
B11: 9 | C11: 639 | D11: =D10+500 -> 4000 | E11: =D11/1000 -> 4 | F11: =C10-C11 -> 10 | G11: =E11-E10 -> 0.5 | H11: =F11/G11 -> 20
B12: E | C12: 634 | D12: ='BC03 (RAC-MOD)'!E7*1000 -> 4480.0612 | E12: =D12/1000 -> 4.4800612 | F12: =C11-C12 -> 5 | G12: =E12-E11 -> 0.48006121 | H12: =F12/G12 -> 10.415338
B14: Sef = | C14: =(((E12/((G4/SQRT(H4))+(G5/SQRT(H5))+(G6/SQRT(H6))+(G7/SQRT(H7))+(G8/SQRT(H8))+(G9/SQRT(H9))+(G10/SQRT(H10))+(G11/SQRT(H11))+(G12/SQRT(H12))))^2)/1000)*1000 -> 31.404046 | D14: (m/km) | E14: m/km
B15: Sef = | C15: =C14/1000 -> 0.031404046 | D15: (m/m) | E15: m/m
B16: Sef = | C16: =C15*100 -> 3.1404046 | D16: (%) | E16: %

Sheet BC05 (RAC-MOD)
A1: ESTUDOS HIDROLÓGICOS
A2: Método Racional Modificado
B3: Estaca: | E3: 314 | F3: + | G3: 11.93 | Q3: UTILIZAR TABELA QUADRO DE CHUVAS ISOZONAS DADOS PLUVIOMÉTRICOS
B4: VIA : | E4: GO-116 | F4: GROTA | K4: TEMPO DE RECORRÊNCIA : | N4: 15 | O4: anos
B5: CURSO D'ÁGUA : | E5: Córrego Piaui | K5: TEMPO DE RECORRÊNCIA : | N5: 25 | O5: anos | Q5: DECLIVIDADE EFETIVA (%): | R5: ='PERFIL BC05'!C16 -> 3.8793747
B6: ÁREA DE CONTRIBUIÇÃO (km²) : | E6: =VLOOKUP(F10,'AUX BACIAS'!$A$2:$D$10,3,0) -> 6.0556073 | K6: TEMPO DE RECORRÊNCIA : | N6: 50 | O6: anos | Q6: DECLIVIDADE MÉDIA (%): | R6: =100*(E8/(E7*1000)) -> 10.753253
B7: COMP. DO TALVEGUE (km) : | E7: =(VLOOKUP(F10,'AUX BACIAS'!$A$2:$D$10,4,0)/1000) -> 4.7334515 | K7: TEMPO DE RECORRÊNCIA : | N7: 100 | O7: anos
B8: DESNÍVEL (m) : | E8: =(INDEX('PERFIL BC05'!$C:$C,MATCH("C",'PERFIL BC05'!$B:$B,0))-INDEX('PERFIL BC05'!$C:$C,MATCH("E",'PERFIL BC05'!$B:$B,0))) -> 509 | K8: COEFICIENTE C: | O8: =H24 -> 0.34358
B9: DECLIVIDADE DA BACIA (%) : | E9: =IF(R5>R6,R6,R5) -> 3.8793747 | K9: TEMPO DE CONCENTRAÇÃO Tc (h) : | O9: =IF(E6<=0.8,0.39*(E7^2/E9)^0.385,0.59*(E7^2/E9)^0.385) -> 1.1589528
E10: Nº Bacia: | F10: {=MID(RIGHT(CELL("nome.arquivo",A1),LEN(CELL("nome.arquivo",A1)) - SEARCH("]",CELL("nome.arquivo",A1))),1,4)} -> BC05 | K10: COEFICIENTE DE RETARDO (φ): | O10: =MAX(0.5,MIN(1,4.38/(E6^0.2*E7))) -> 0.64545303
B11: Tipo de Relevo | C11: Ondulado
B12: Orografia | C12: B | J12: CHUVA DE PROJETO | Q12: Auxiliar - Não apagar
B13: * Classificação de orografia segundo a IP 03 – Goinfra – Estudos hidrológicos | J13: TR | K13: D tc (min) | L13: Po (mm) | N13: I (mm/min) | Q13: {=IFERROR(_xlfn.LET( _xlpm.Q,M20, _xlpm.Tipos,[3]Base_Bueiros!$C$2:$C$10, _xlpm.Dims,[3]Base_Bueiros!$D$2:$D$10, _xlpm.Vazoes,[3]Base_Bueiros!$F$2:$F$10, _xlpm.Diam,VALUE(_xlpm.Dims), _xlpm.MenorDiam,_xlfn.AGGREGATE(15,6,_xlpm.Diam/(_xlpm.Vazoes>=_xlpm.Q),1), _xlpm.MenorVazao,_xlfn.AGGREGATE(15,6,_xlpm.Vazoes/((_xlpm.Vazoes>=_xlpm.Q)*(_xlpm.Diam=_xlpm.MenorDiam)),1), _xlpm.Linha,MATCH(_xlpm.MenorVazao,_xlpm.Vazoes,0), INDEX(_xlpm.Tipos,_xlpm.Linha)&" d="&INDEX(_xlpm.Dims,_xlpm.Linha)&"m" ),"Não atende em canal 15 anos. Dimensionar para 25 anos")} -> Não atende em canal 15 anos. Dimensionar para 25 anos | S13: =IF(Q13="Não atende em canal 15 anos. Dimensionar para 25 anos",25,15) -> 25 | X13: ax | Y13: + | Z13: b | AB13: ='BC01 (RAC)'!AB13 -> ax (1-24h) | AC13: Método para C
J14: 15 anos | K14: =$O$9*60 -> 69.537168 | L14: =IF($O$9<=1,(X14*LN((K14/60)))+Z14,(AB14*LN((K14/60)))+Z14) -> 86.948051 | N14: =L14/K14 -> 1.2503824 | Q14: {=IFERROR(_xlfn.LET( _xlpm.Q,M21, _xlpm.Tipos,[3]Base_Bueiros!$C$20:$C$28, _xlpm.Dims,[3]Base_Bueiros!$D$20:$D$28, _xlpm.Vazoes,[3]Base_Bueiros!$F$20:$F$28, _xlpm.Diam,VALUE(_xlpm.Dims), _xlpm.MenorDiam,_xlfn.AGGREGATE(15,6,_xlpm.Diam/(_xlpm.Vazoes>=_xlpm.Q),1), _xlpm.MenorVazao,_xlfn.AGGREGATE(15,6,_xlpm.Vazoes/((_xlpm.Vazoes>=_xlpm.Q)*(_xlpm.Diam=_xlpm.MenorDiam)),1), _xlpm.Linha,MATCH(_xlpm.MenorVazao,_xlpm.Vazoes,0), _xlpm.Tipo,TRIM(IFERROR(LEFT(INDEX(_xlpm.Tipos,_xlpm.Linha),FIND(" OU ",INDEX(_xlpm.Tipos,_xlpm.Linha))-1),INDEX(_xlpm.Tipos,_xlpm.Linha))), _xlpm.Tipo&" d="&INDEX(_xlpm.Dims,_xlpm.Linha)&"m" ),"Não atende em orifício 25 anos. Dimensionar para 50 anos")} -> Não atende em orifício 25 anos. Dimensionar para 50 anos | S14: =IF(Q14="Não atende em orifício 25 anos. Dimensionar para 50 anos",50,25) -> 50 | X14: ='BC01 (RAC)'!X14 -> 26.41506 | Z14: ='BC01 (RAC)'!Z14 -> 83.379769 | AB14: ='BC01 (RAC)'!AB14 -> 24.188986 | AC14: =IF(C11="Plano","Tabelado",IF(C11="Ondulado","Tabelado",IF(C11="Montanhoso","Tabelado","Ponderado"))) -> Tabelado
J15: 25 anos | K15: =$O$9*60 -> 69.537168 | L15: =IF($O$9<=1,(X15*LN((K15/60)))+Z15,(AB15*LN((K15/60)))+Z15) -> 95.844352 | N15: =L15/K15 -> 1.3783183 | X15: ='BC01 (RAC)'!X15 -> 29.043207 | Z15: ='BC01 (RAC)'!Z15 -> 91.924418 | AB15: ='BC01 (RAC)'!AB15 -> 26.572791
J16: 50 anos | K16: =$O$9*60 -> 69.537168 | L16: =IF($O$9<=1,(X16*LN((K16/60)))+Z16,(AB16*LN((K16/60)))+Z16) -> 107.43899 | N16: =L16/K16 -> 1.5450584 | X16: ='BC01 (RAC)'!X16 -> 32.43716 | Z16: ='BC01 (RAC)'!Z16 -> 103.04595 | AB16: ='BC01 (RAC)'!AB16 -> 29.779923
J17: 100 anos | K17: =$O$9*60 -> 69.537168 | L17: =IF($O$9<=1,(X17*LN((K17/60)))+Z17,(AB17*LN((K17/60)))+Z17) -> 118.72444 | N17: =L17/K17 -> 1.7073522 | X17: ='BC01 (RAC)'!X17 -> 37.177213 | Z17: ='BC01 (RAC)'!Z17 -> 113.85574 | AB17: ='BC01 (RAC)'!AB17 -> 33.004345
B18: COMPOSIÇÃO DE ÁREA "C"
D19: m² | E19: km² | F19: C | G19: % | J19: Resultados | K19: Recorrência | M19: Qmáx
B20: Área total | D20: =E20*10^6 -> 6055607.3 | E20: =E6 -> 6.0556073 | F20: - | G20: - | H20: - | K20: Q15 = | M20: =0.278*$O$8*(N14*60)*$E$6*$O$10 -> 28.008453 | N20: m³/s
B21: Culturas e pastagens terraceadas | D21: =$D$20*G21 -> 3671514.7 | E21: =D21/10^6 -> 3.6715147 | F21: {=_xlfn.LET( _xlpm.superficie,B21, _xlpm.oro,$C$12, _xlpm.terreno,$C$11, _xlpm.metodo,$AC$14, _xlpm.linInicial,MATCH(_xlpm.superficie,C_CN_IP03!$B$4:$B$19,0), _xlpm.lin,_xlpm.linInicial+MATCH(_xlpm.oro,INDEX(C_CN_IP03!$C$4:$C$19,_xlpm.linInicial):INDEX(C_CN_IP03!$C$4:$C$19,_xlpm.linInicial+3),0)-1, IF( _xlpm.metodo="Tabelado", _xlfn.LET( _xlpm.col,MATCH(_xlpm.terreno,C_CN_IP03!$D$2:$I$2,0), INDEX(C_CN_IP03!$D$4:$I$19,_xlpm.lin,_xlpm.col) ), IF( _xlpm.metodo="Ponderado", IF( _xlpm.terreno="Levemente ondulado", AVERAGE( INDEX(C_CN_IP03!$D$4:$I$19,_xlpm.lin,1), INDEX(C_CN_IP03!$D$4:$I$19,_xlpm.lin,3) ), IF( _xlpm.terreno="Muito ondulado", AVERAGE( INDEX(C_CN_IP03!$D$4:$I$19,_xlpm.lin,3), INDEX(C_CN_IP03!$D$4:$I$19,_xlpm.lin,5) ), "Condição de terreno não reconhecida" ) ), "Método não reconhecido" ) ) )} -> 0.35 | G21: 0.6063 | H21: =(G21*(F21)) -> 0.212205 | K21: Q25 = | M21: =0.278*$O$8*(N15*60)*$E$6*$O$10 -> 30.874206 | N21: m³/s
B22: Cerrados, pastagens e matas ralas | D22: =$D$20*G22 -> 1606552.6 | E22: =D22*(10^-6) -> 1.6065526 | F22: {=_xlfn.LET( _xlpm.superficie,B22, _xlpm.oro,$C$12, _xlpm.terreno,$C$11, _xlpm.metodo,$AC$14, _xlpm.linInicial,MATCH(_xlpm.superficie,C_CN_IP03!$B$4:$B$19,0), _xlpm.lin,_xlpm.linInicial+MATCH(_xlpm.oro,INDEX(C_CN_IP03!$C$4:$C$19,_xlpm.linInicial):INDEX(C_CN_IP03!$C$4:$C$19,_xlpm.linInicial+3),0)-1, IF( _xlpm.metodo="Tabelado", _xlfn.LET( _xlpm.col,MATCH(_xlpm.terreno,C_CN_IP03!$D$2:$I$2,0), INDEX(C_CN_IP03!$D$4:$I$19,_xlpm.lin,_xlpm.col) ), IF( _xlpm.metodo="Ponderado", IF( _xlpm.terreno="Levemente ondulado", AVERAGE( INDEX(C_CN_IP03!$D$4:$I$19,_xlpm.lin,1), INDEX(C_CN_IP03!$D$4:$I$19,_xlpm.lin,3) ), IF( _xlpm.terreno="Muito ondulado", AVERAGE( INDEX(C_CN_IP03!$D$4:$I$19,_xlpm.lin,3), INDEX(C_CN_IP03!$D$4:$I$19,_xlpm.lin,5) ), "Condição de terreno não reconhecida" ) ), "Método não reconhecido" ) ) )} -> 0.35 | G22: 0.2653 | H22: =(G22*(F22)) -> 0.092855 | K22: Q50 = | M22: =0.278*$O$8*(N16*60)*$E$6*$O$10 -> 34.609169 | N22: m³/s
B23: Culturas terraceadas | D23: =$D$20*G23 -> 777539.97 | E23: =D23*(10^-6) -> 0.77753997 | F23: {=_xlfn.LET( _xlpm.superficie,B23, _xlpm.oro,$C$12, _xlpm.terreno,$C$11, _xlpm.metodo,$AC$14, _xlpm.linInicial,MATCH(_xlpm.superficie,C_CN_IP03!$B$4:$B$19,0), _xlpm.lin,_xlpm.linInicial+MATCH(_xlpm.oro,INDEX(C_CN_IP03!$C$4:$C$19,_xlpm.linInicial):INDEX(C_CN_IP03!$C$4:$C$19,_xlpm.linInicial+3),0)-1, IF( _xlpm.metodo="Tabelado", _xlfn.LET( _xlpm.col,MATCH(_xlpm.terreno,C_CN_IP03!$D$2:$I$2,0), INDEX(C_CN_IP03!$D$4:$I$19,_xlpm.lin,_xlpm.col) ), IF( _xlpm.metodo="Ponderado", IF( _xlpm.terreno="Levemente ondulado", AVERAGE( INDEX(C_CN_IP03!$D$4:$I$19,_xlpm.lin,1), INDEX(C_CN_IP03!$D$4:$I$19,_xlpm.lin,3) ), IF( _xlpm.terreno="Muito ondulado", AVERAGE( INDEX(C_CN_IP03!$D$4:$I$19,_xlpm.lin,3), INDEX(C_CN_IP03!$D$4:$I$19,_xlpm.lin,5) ), "Condição de terreno não reconhecida" ) ), "Método não reconhecido" ) ) )} -> 0.3 | G23: 0.1284 | H23: =(G23*(F23)) -> 0.03852 | K23: Q100 = | M23: =0.278*$O$8*(N17*60)*$E$6*$O$10 -> 38.244535 | N23: m³/s
B24: C adotado | H24: =(SUM(H21:H23)) -> 0.34358
B25: * Tabela de coeficientes de C e CN - IP 03 – Goinfra – Estudos hidrológicos | J25: OBRA PROJETADA
